Workbook

Sheet QUOTATION
AD3: MBF JOINT STOCK COMPANY
U4: No. 58, Gieng Hamlet, Co Dien A Village, Thanh Tri Commune, Hanoi, Vietnam
Z5: Tel: 84-24-39449616 - Fax 84-24-39449618
AN6: http://mbf.com.vn
B9: To: | E9: CANON VIETNAM CO., LTD-THANGLONG FACTORY (CTL) CANON VIETNAM CO., LTD-QUEVO FACTORY (CQV) CANON VIETNAM CO., LTD-TIENSON FACTORY (CTS) | AE9: Ref No: | AH9: Quotation no: | AM9: MBF-202607-00
B10: Attn.: | E10: Mr. Shigeyuki Okamoto | AE10: Issue Date: | AH10: 46132
E11: General Director | AE11: Effect Date: | AH11: 46204
B12: Tel: | E12: +(84)(24)-3.881.2111 +(84)(222)-3.622.111 +(84)(222)-3.712.111 | AE12: Expiry Date: | AH12: 46568
B13: From: | E13: Ms. Nguyen Thu Thuy - Director | AE13: Contact: | AH13: Name: | AK13: Ms. Thanh Mai
B14: Subject: | E14: GENERAL QUOTATION FOR HANDLING IMPORT-EXPORT CARGO | AH14: Tel: | AK14: 0981.639.905
E15: FOLLOWING CONTRACT NO: | P15: CVNLOG-MBF-2026-001 | AH15: Email | AK15: doc01@mbf.com.vn
B18: Dear sirs,
B20: Thank you very much for your kind attention and support to our company as always.
B21: We would like to send you herewith our revised Quotation as attachment.
D25: · | E25: This Quotation is replaced for Quotation No: | T25: 1st version
D26: · | E26: This quotation rate is based on fuel price: | T26: 35,440 VND per liter.
B32: The quotation will be renewed automatically after the above expired date if there is no contrary from any party.
B33: We deeply wish that our offer will satisfy your requirement. If you have any comment, please feel free to contact us at anytime.
B34: Your kind attention to above would be highly appreciated.
C47: MBF JOINT STOCK COMPANY | AE47: CANON VIETNAM CO., LTD
D55: Ms. Nguyen Thu Thuy | AJ55: Mr. Shigeyuki Okamoto
F56: Director | AN56: General Director

Sheet import
F1: LOGISTICS QUOTATION LIST OF HANDLING IMPORT/EXPORT CARGO
B2: Issued by MBF JOINT STOCK COMPANY on: | I2: =QUOTATION!AH10 -> 46132
B3: This attached file is an integral part of the Quotation No: | I3: =+QUOTATION!AM9 -> MBF-202607-00 | K3: effective date: | L3: =QUOTATION!AH11 -> 46204
B5: 1. | C5: CUSTOMS CLEARANCE FEE
C7: Factory | E7: Kind | F7: Item | J7: 40FT | K7: 20FT | L7: LCL | M7: Air | N7: Domestics | O7: Remark
J8: Container | K8: Container | L8: CDS | M8: CDS | N8: CDS
C9: TL/TS/QV | E9: Export/ Import | F9: Local custom clerance fee | J9: 250000 | K9: 250000 | L9: 250000 | M9: 250000 | N9: 350000
F10: Port custom clerance fee | J10: 200000 | K10: 200000 | L10: 200000 | M10: 200000 | N10: 0
F11: Total | J11: =J9+J10 -> 450000 | K11: =K9+K10 -> 450000 | L11: =L9+L10 -> 450000 | M11: =M9+M10 -> 450000 | N11: =N9+N10 -> 350000
C12: Branch CDS (over 50 item lines) | J12: 200000 | K12: 200000 | L12: 200000 | M12: 200000 | N12: 200000
C13: Additional CDS (2 or more different CDS for each shipment/ each invoice, except branch CDS as mentioned above) | J13: 250000 | K13: 250000 | L13: - | M13: - | N13: -
C14: Combine container (cargo of 2 or 3 factories combined in 1 container), from the 2nd CDS | J14: 250000 | K14: 250000 | L14: - | M14: - | N14: -
B16: 2. | C16: DRAYAGE BY TRIP
B17: 2.1. | C17: HAI PHONG PORT
B18: 2.1.1 | C18: TRUCK DISCONNECT WITH CHASSIS TO HAI PHONG PORT
C20: KIND | D20: Routing | I20: Distance ( km) | J20: Transportation fee | L20: Fuel fee | N20: Total
D21: FROM | E21: TO | F21: TO | G21: TO | H21: TO | J21: 40FT | K21: 20FT | L21: 40FT | M21: 20FT | N21: 40FT | O21: 20FT
C22: Transportation 1 way of Import/Export | D22: HPP | E22: TL | H22: HPP | I22: 287 | J22: 3320000 | K22: 3320000 | L22: 2644533 | M22: 2644533 | N22: =J22+L22 -> 5964533 | O22: =K22+M22 -> 5964533 | Q22: 3320000 | R22: 3320000 | S22: 2644532.8 | T22: 2644532.8 | U22: 5964532.8 | V22: 5964532.8 | W22: =+J22-Q22 -> 0 | X22: =+K22-R22 -> 0 | Y22: =+L22-S22 -> 0.2 | Z22: =+M22-T22 -> 0.2 | AA22: =+N22-U22 -> 0.2 | AB22: =+O22-V22 -> 0.2
D23: HPP | E23: TS | H23: HPP | I23: 266 | J23: 3000000 | K23: 3000000 | L23: 2451030 | M23: 2451030 | N23: =J23+L23 -> 5451030 | O23: =K23+M23 -> 5451030 | Q23: 3000000 | R23: 3000000 | S23: 2451030.4 | T23: 2451030.4 | U23: 5451030.4 | V23: 5451030.4 | W23: =+J23-Q23 -> 0 | X23: =+K23-R23 -> 0 | Y23: =+L23-S23 -> -0.4 | Z23: =+M23-T23 -> -0.4 | AA23: =+N23-U23 -> -0.4 | AB23: =+O23-V23 -> -0.4
D24: HPP | E24: QV | H24: HPP | I24: 255 | J24: 3000000 | K24: 3000000 | L24: 2349672 | M24: 2349672 | N24: =J24+L24 -> 5349672 | O24: =K24+M24 -> 5349672 | Q24: 3000000 | R24: 3000000 | S24: 2349672 | T24: 2349672 | U24: 5349672 | V24: 5349672 | W24: =+J24-Q24 -> 0 | X24: =+K24-R24 -> 0 | Y24: =+L24-S24 -> 0 | Z24: =+M24-T24 -> 0 | AA24: =+N24-U24 -> 0 | AB24: =+O24-V24 -> 0
D25: HPP | E25: TL | F25: TS | H25: HPP | I25: 312 | J25: 3800000 | K25: 3800000 | L25: 2874893 | M25: 2874893 | N25: =J25+L25 -> 6674893 | O25: =K25+M25 -> 6674893 | Q25: 3800000 | R25: 3800000 | S25: 2874892.8 | T25: 2874892.8 | U25: 6674892.8 | V25: 6674892.8 | W25: =+J25-Q25 -> 0 | X25: =+K25-R25 -> 0 | Y25: =+L25-S25 -> 0.2 | Z25: =+M25-T25 -> 0.2 | AA25: =+N25-U25 -> 0.2 | AB25: =+O25-V25 -> 0.2
D26: HPP | E26: TL | F26: QV | H26: HPP | I26: 320 | J26: 3820000 | K26: 3820000 | L26: 2948608 | M26: 2948608 | N26: =J26+L26 -> 6768608 | O26: =K26+M26 -> 6768608 | Q26: 3820000 | R26: 3820000 | S26: 2948608 | T26: 2948608 | U26: 6768608 | V26: 6768608 | W26: =+J26-Q26 -> 0 | X26: =+K26-R26 -> 0 | Y26: =+L26-S26 -> 0 | Z26: =+M26-T26 -> 0 | AA26: =+N26-U26 -> 0 | AB26: =+O26-V26 -> 0
D27: HPP | E27: TS | F27: QV | H27: HPP | I27: 280 | J27: 3390000 | K27: 3390000 | L27: 2580032 | M27: 2580032 | N27: =J27+L27 -> 5970032 | O27: =K27+M27 -> 5970032 | Q27: 3390000 | R27: 3390000 | S27: 2580032 | T27: 2580032 | U27: 5970032 | V27: 5970032 | W27: =+J27-Q27 -> 0 | X27: =+K27-R27 -> 0 | Y27: =+L27-S27 -> 0 | Z27: =+M27-T27 -> 0 | AA27: =+N27-U27 -> 0 | AB27: =+O27-V27 -> 0
D28: HPP | E28: TL | F28: TS | G28: QV | H28: HPP | I28: 366 | J28: 4120000 | K28: 4120000 | L28: 3372470 | M28: 3372470 | N28: =J28+L28 -> 7492470 | O28: =K28+M28 -> 7492470 | Q28: 4120000 | R28: 4120000 | S28: 3372470.4 | T28: 3372470.4 | U28: 7492470.4 | V28: 7492470.4 | W28: =+J28-Q28 -> 0 | X28: =+K28-R28 -> 0 | Y28: =+L28-S28 -> -0.4 | Z28: =+M28-T28 -> -0.4 | AA28: =+N28-U28 -> -0.4 | AB28: =+O28-V28 -> -0.4
D29: HPP | E29: CEV | H29: HPP | I29: 195 | J29: 2720000 | K29: 2720000 | L29: 1796808 | M29: 1796808 | N29: =J29+L29 -> 4516808 | O29: =K29+M29 -> 4516808 | Q29: 2720000 | R29: 2720000 | S29: 1796808 | T29: 1796808 | U29: 4516808 | V29: 4516808 | W29: =+J29-Q29 -> 0 | X29: =+K29-R29 -> 0 | Y29: =+L29-S29 -> 0 | Z29: =+M29-T29 -> 0 | AA29: =+N29-U29 -> 0 | AB29: =+O29-V29 -> 0
D30: HPP | E30: CEV | F30: TL | H30: HPP | I30: 288 | J30: 3470000 | K30: 3470000 | L30: 2653747 | M30: 2653747 | N30: =J30+L30 -> 6123747 | O30: =K30+M30 -> 6123747 | Q30: 3470000 | R30: 3470000 | S30: 2653747.2 | T30: 2653747.2 | U30: 6123747.2 | V30: 6123747.2 | W30: =+J30-Q30 -> 0 | X30: =+K30-R30 -> 0 | Y30: =+L30-S30 -> -0.2 | Z30: =+M30-T30 -> -0.2 | AA30: =+N30-U30 -> -0.2 | AB30: =+O30-V30 -> -0.2
D31: HPP | E31: CEV | F31: TS | H31: HPP | I31: 276 | J31: 3430000 | K31: 3430000 | L31: 2543174 | M31: 2543174 | N31: =J31+L31 -> 5973174 | O31: =K31+M31 -> 5973174 | Q31: 3430000 | R31: 3430000 | S31: 2543174.4 | T31: 2543174.4 | U31: 5973174.4 | V31: 5973174.4 | W31: =+J31-Q31 -> 0 | X31: =+K31-R31 -> 0 | Y31: =+L31-S31 -> -0.4 | Z31: =+M31-T31 -> -0.4 | AA31: =+N31-U31 -> -0.4 | AB31: =+O31-V31 -> -0.4
D32: HPP | E32: VSIP | H32: HPP | I32: 246 | J32: 3070000 | K32: 3070000 | L32: 2266742 | M32: 2266742 | N32: =J32+L32 -> 5336742 | O32: =K32+M32 -> 5336742 | Q32: 3070000 | R32: 3070000 | S32: 2266742.4 | T32: 2266742.4 | U32: 5336742.4 | V32: 5336742.4 | W32: =+J32-Q32 -> 0 | X32: =+K32-R32 -> 0 | Y32: =+L32-S32 -> -0.4 | Z32: =+M32-T32 -> -0.4 | AA32: =+N32-U32 -> -0.4 | AB32: =+O32-V32 -> -0.4
D33: HPP | E33: VSIP | F33: TS | H33: HPP | I33: 266 | J33: 3400000 | K33: 3400000 | L33: 2451030 | M33: 2451030 | N33: =J33+L33 -> 5851030 | O33: =K33+M33 -> 5851030 | Q33: 3400000 | R33: 3400000 | S33: 2451030.4 | T33: 2451030.4 | U33: 5851030.4 | V33: 5851030.4 | W33: =+J33-Q33 -> 0 | X33: =+K33-R33 -> 0 | Y33: =+L33-S33 -> -0.4 | Z33: =+M33-T33 -> -0.4 | AA33: =+N33-U33 -> -0.4 | AB33: =+O33-V33 -> -0.4
D34: HPP | E34: VSIP | F34: QV | H34: HPP | I34: 268 | J34: 3410000 | K34: 3410000 | L34: 2469459 | M34: 2469459 | N34: =J34+L34 -> 5879459 | O34: =K34+M34 -> 5879459 | Q34: 3410000 | R34: 3410000 | S34: 2469459.2 | T34: 2469459.2 | U34: 5879459.2 | V34: 5879459.2 | W34: =+J34-Q34 -> 0 | X34: =+K34-R34 -> 0 | Y34: =+L34-S34 -> -0.2 | Z34: =+M34-T34 -> -0.2 | AA34: =+N34-U34 -> -0.2 | AB34: =+O34-V34 -> -0.2
D35: HPP | E35: VSIP | F35: TS | G35: QV | H35: HPP | I35: 288 | J35: 3620000 | K35: 3620000 | L35: 2653747 | M35: 2653747 | N35: =J35+L35 -> 6273747 | O35: =K35+M35 -> 6273747 | Q35: 3620000 | R35: 3620000 | S35: 2653747.2 | T35: 2653747.2 | U35: 6273747.2 | V35: 6273747.2 | W35: =+J35-Q35 -> 0 | X35: =+K35-R35 -> 0 | Y35: =+L35-S35 -> -0.2 | Z35: =+M35-T35 -> -0.2 | AA35: =+N35-U35 -> -0.2 | AB35: =+O35-V35 -> -0.2
C36: Transportation 1 way of Import/Export | D36: ICDQV | E36: TL | H36: HPP | I36: 287 | J36: 3320000 | K36: 3320000 | L36: 2644533 | M36: 2644533 | N36: =J36+L36 -> 5964533 | O36: =K36+M36 -> 5964533 | Q36: 3320000 | R36: 3320000 | S36: 2644532.8 | T36: 2644532.8 | U36: 5964532.8 | V36: 5964532.8 | W36: =+J36-Q36 -> 0 | X36: =+K36-R36 -> 0 | Y36: =+L36-S36 -> 0.2 | Z36: =+M36-T36 -> 0.2 | AA36: =+N36-U36 -> 0.2 | AB36: =+O36-V36 -> 0.2
D37: ICDQV | E37: TS | H37: HPP | I37: 266 | J37: 3050000 | K37: 3050000 | L37: 2451030 | M37: 2451030 | N37: =J37+L37 -> 5501030 | O37: =K37+M37 -> 5501030 | Q37: 3050000 | R37: 3050000 | S37: 2451030.4 | T37: 2451030.4 | U37: 5501030.4 | V37: 5501030.4 | W37: =+J37-Q37 -> 0 | X37: =+K37-R37 -> 0 | Y37: =+L37-S37 -> -0.4 | Z37: =+M37-T37 -> -0.4 | AA37: =+N37-U37 -> -0.4 | AB37: =+O37-V37 -> -0.4
D38: ICDQV | E38: QV | H38: HPP | I38: 255 | J38: 3010000 | K38: 3010000 | L38: 2349672 | M38: 2349672 | N38: =J38+L38 -> 5359672 | O38: =K38+M38 -> 5359672 | Q38: 3010000 | R38: 3010000 | S38: 2349672 | T38: 2349672 | U38: 5359672 | V38: 5359672 | W38: =+J38-Q38 -> 0 | X38: =+K38-R38 -> 0 | Y38: =+L38-S38 -> 0 | Z38: =+M38-T38 -> 0 | AA38: =+N38-U38 -> 0 | AB38: =+O38-V38 -> 0
D39: ICDQV | E39: TL | F39: TS | H39: HPP | I39: 312 | J39: 3800000 | K39: 3800000 | L39: 2874893 | M39: 2874893 | N39: =J39+L39 -> 6674893 | O39: =K39+M39 -> 6674893 | Q39: 3800000 | R39: 3800000 | S39: 2874892.8 | T39: 2874892.8 | U39: 6674892.8 | V39: 6674892.8 | W39: =+J39-Q39 -> 0 | X39: =+K39-R39 -> 0 | Y39: =+L39-S39 -> 0.2 | Z39: =+M39-T39 -> 0.2 | AA39: =+N39-U39 -> 0.2 | AB39: =+O39-V39 -> 0.2
D40: ICDQV | E40: TL | F40: QV | H40: HPP | I40: 320 | J40: 3820000 | K40: 3820000 | L40: 2948608 | M40: 2948608 | N40: =J40+L40 -> 6768608 | O40: =K40+M40 -> 6768608 | Q40: 3820000 | R40: 3820000 | S40: 2948608 | T40: 2948608 | U40: 6768608 | V40: 6768608 | W40: =+J40-Q40 -> 0 | X40: =+K40-R40 -> 0 | Y40: =+L40-S40 -> 0 | Z40: =+M40-T40 -> 0 | AA40: =+N40-U40 -> 0 | AB40: =+O40-V40 -> 0
D41: ICDQV | E41: TS | F41: QV | H41: HPP | I41: 280 | J41: 3390000 | K41: 3390000 | L41: 2580032 | M41: 2580032 | N41: =J41+L41 -> 5970032 | O41: =K41+M41 -> 5970032 | Q41: 3390000 | R41: 3390000 | S41: 2580032 | T41: 2580032 | U41: 5970032 | V41: 5970032 | W41: =+J41-Q41 -> 0 | X41: =+K41-R41 -> 0 | Y41: =+L41-S41 -> 0 | Z41: =+M41-T41 -> 0 | AA41: =+N41-U41 -> 0 | AB41: =+O41-V41 -> 0
D42: ICDQV | E42: TL | F42: TS | G42: QV | H42: HPP | I42: 366 | J42: 4120000 | K42: 4120000 | L42: 3372470 | M42: 3372470 | N42: =J42+L42 -> 7492470 | O42: =K42+M42 -> 7492470 | Q42: 4120000 | R42: 4120000 | S42: 3372470.4 | T42: 3372470.4 | U42: 7492470.4 | V42: 7492470.4 | W42: =+J42-Q42 -> 0 | X42: =+K42-R42 -> 0 | Y42: =+L42-S42 -> -0.4 | Z42: =+M42-T42 -> -0.4 | AA42: =+N42-U42 -> -0.4 | AB42: =+O42-V42 -> -0.4
D43: ICDTP | E43: TL | H43: HPP | I43: 287 | J43: 3320000 | K43: 3320000 | L43: 2644533 | M43: 2644533 | N43: =J43+L43 -> 5964533 | O43: =K43+M43 -> 5964533 | Q43: 3320000 | R43: 3320000 | S43: 2644532.8 | T43: 2644532.8 | U43: 5964532.8 | V43: 5964532.8 | W43: =+J43-Q43 -> 0 | X43: =+K43-R43 -> 0 | Y43: =+L43-S43 -> 0.2 | Z43: =+M43-T43 -> 0.2 | AA43: =+N43-U43 -> 0.2 | AB43: =+O43-V43 -> 0.2
D44: ICDTP | E44: TS | H44: HPP | I44: 266 | J44: 3050000 | K44: 3050000 | L44: 2451030 | M44: 2451030 | N44: =J44+L44 -> 5501030 | O44: =K44+M44 -> 5501030 | Q44: 3050000 | R44: 3050000 | S44: 2451030.4 | T44: 2451030.4 | U44: 5501030.4 | V44: 5501030.4 | W44: =+J44-Q44 -> 0 | X44: =+K44-R44 -> 0 | Y44: =+L44-S44 -> -0.4 | Z44: =+M44-T44 -> -0.4 | AA44: =+N44-U44 -> -0.4 | AB44: =+O44-V44 -> -0.4
...

Sheet Attachmen(disconnect & conn (2
F1: LOGISTICS QUOTATION LIST OF HANDLING IMPORT/EXPORT CARGO
B2: Issued by MBF JOINT STOCK COMPANY on: | I2: =QUOTATION!AH10 -> 46132
B3: This attached file is an integral part of the Quotation No: | I3: =+QUOTATION!AM9 -> MBF-202607-00 | K3: effective date: | L3: =QUOTATION!AH11 -> 46204
B5: 1. | C5: CUSTOMS CLEARANCE FEE
C7: Factory | E7: Kind | F7: Item | J7: 40FT | K7: 20FT | L7: LCL | M7: Air | N7: Domestics | O7: Remark
J8: Container | K8: Container | L8: CDS | M8: CDS | N8: CDS
C9: TL/TS/QV | E9: Export/ Import | F9: Local custom clerance fee | J9: 200000 | K9: 200000 | L9: 200000 | M9: 200000 | N9: 200000
F10: Port custom clerance fee | J10: 100000 | K10: 100000 | L10: 100000 | M10: 100000 | N10: 0
F11: Total | J11: =J9+J10 -> 300000 | K11: =K9+K10 -> 300000 | L11: =L9+L10 -> 300000 | M11: =M9+M10 -> 300000 | N11: =N9+N10 -> 200000
C12: Branch CDS (over 50 item lines) | J12: 100000 | K12: 100000 | L12: 100000 | M12: 100000 | N12: 100000
C13: Additional CDS (2 or more different CDS for each shipment/ each invoice, except branch CDS as mentioned above) | J13: 200000 | K13: 200000 | L13: - | M13: - | N13: -
C14: Combine container (cargo of 2 or 3 factories combined in 1 container), from the 2nd CDS | J14: 200000 | K14: 200000 | L14: - | M14: - | N14: -
B16: 2. | C16: DRAYAGE BY TRIP
B17: 2.1. | C17: HAI PHONG PORT
B18: 2.1.1 | C18: TRUCK DISCONNECT WITH CHASSIS TO HAI PHONG PORT
C20: KIND | D20: Routing | I20: Distance ( km) | J20: Transportation fee | L20: Fuel fee | N20: Total
D21: FROM | E21: TO | F21: TO | G21: TO | H21: TO | J21: 40FT | K21: 20FT | L21: 40FT | M21: 20FT | N21: 40FT | O21: 20FT
C22: Transportation 1 way of Import/Export | D22: HPP | E22: TL | H22: HPP | I22: 287 | J22: 3320000 | K22: 3320000 | L22: 2644533 | M22: 2644533 | N22: =J22+L22 -> 5964533 | O22: =K22+M22 -> 5964533 | Q22: 3320000 | R22: 3320000 | S22: 2644532.8 | T22: 2644532.8 | U22: 5964532.8 | V22: 5964532.8 | W22: =+J22-Q22 -> 0 | X22: =+K22-R22 -> 0 | Y22: =+L22-S22 -> 0.2 | Z22: =+M22-T22 -> 0.2 | AA22: =+N22-U22 -> 0.2 | AB22: =+O22-V22 -> 0.2
D23: HPP | E23: TS | H23: HPP | I23: 266 | J23: 3000000 | K23: 3000000 | L23: 2451030 | M23: 2451030 | N23: =J23+L23 -> 5451030 | O23: =K23+M23 -> 5451030 | Q23: 3000000 | R23: 3000000 | S23: 2451030.4 | T23: 2451030.4 | U23: 5451030.4 | V23: 5451030.4 | W23: =+J23-Q23 -> 0 | X23: =+K23-R23 -> 0 | Y23: =+L23-S23 -> -0.4 | Z23: =+M23-T23 -> -0.4 | AA23: =+N23-U23 -> -0.4 | AB23: =+O23-V23 -> -0.4
D24: HPP | E24: QV | H24: HPP | I24: 255 | J24: 3000000 | K24: 3000000 | L24: 2349672 | M24: 2349672 | N24: =J24+L24 -> 5349672 | O24: =K24+M24 -> 5349672 | Q24: 3000000 | R24: 3000000 | S24: 2349672 | T24: 2349672 | U24: 5349672 | V24: 5349672 | W24: =+J24-Q24 -> 0 | X24: =+K24-R24 -> 0 | Y24: =+L24-S24 -> 0 | Z24: =+M24-T24 -> 0 | AA24: =+N24-U24 -> 0 | AB24: =+O24-V24 -> 0
D25: HPP | E25: TL | F25: TS | H25: HPP | I25: 312 | J25: 3800000 | K25: 3800000 | L25: 2874893 | M25: 2874893 | N25: =J25+L25 -> 6674893 | O25: =K25+M25 -> 6674893 | Q25: 3800000 | R25: 3800000 | S25: 2874892.8 | T25: 2874892.8 | U25: 6674892.8 | V25: 6674892.8 | W25: =+J25-Q25 -> 0 | X25: =+K25-R25 -> 0 | Y25: =+L25-S25 -> 0.2 | Z25: =+M25-T25 -> 0.2 | AA25: =+N25-U25 -> 0.2 | AB25: =+O25-V25 -> 0.2
D26: HPP | E26: TL | F26: QV | H26: HPP | I26: 320 | J26: 3820000 | K26: 3820000 | L26: 2948608 | M26: 2948608 | N26: =J26+L26 -> 6768608 | O26: =K26+M26 -> 6768608 | Q26: 3820000 | R26: 3820000 | S26: 2948608 | T26: 2948608 | U26: 6768608 | V26: 6768608 | W26: =+J26-Q26 -> 0 | X26: =+K26-R26 -> 0 | Y26: =+L26-S26 -> 0 | Z26: =+M26-T26 -> 0 | AA26: =+N26-U26 -> 0 | AB26: =+O26-V26 -> 0
D27: HPP | E27: TS | F27: QV | H27: HPP | I27: 280 | J27: 3390000 | K27: 3390000 | L27: 2580032 | M27: 2580032 | N27: =J27+L27 -> 5970032 | O27: =K27+M27 -> 5970032 | Q27: 3390000 | R27: 3390000 | S27: 2580032 | T27: 2580032 | U27: 5970032 | V27: 5970032 | W27: =+J27-Q27 -> 0 | X27: =+K27-R27 -> 0 | Y27: =+L27-S27 -> 0 | Z27: =+M27-T27 -> 0 | AA27: =+N27-U27 -> 0 | AB27: =+O27-V27 -> 0
D28: HPP | E28: TL | F28: TS | G28: QV | H28: HPP | I28: 366 | J28: 4120000 | K28: 4120000 | L28: 3372470 | M28: 3372470 | N28: =J28+L28 -> 7492470 | O28: =K28+M28 -> 7492470 | Q28: 4120000 | R28: 4120000 | S28: 3372470.4 | T28: 3372470.4 | U28: 7492470.4 | V28: 7492470.4 | W28: =+J28-Q28 -> 0 | X28: =+K28-R28 -> 0 | Y28: =+L28-S28 -> -0.4 | Z28: =+M28-T28 -> -0.4 | AA28: =+N28-U28 -> -0.4 | AB28: =+O28-V28 -> -0.4
D29: HPP | E29: CEV | H29: HPP | I29: 195 | J29: 2720000 | K29: 2720000 | L29: 1796808 | M29: 1796808 | N29: =J29+L29 -> 4516808 | O29: =K29+M29 -> 4516808 | Q29: 2720000 | R29: 2720000 | S29: 1796808 | T29: 1796808 | U29: 4516808 | V29: 4516808 | W29: =+J29-Q29 -> 0 | X29: =+K29-R29 -> 0 | Y29: =+L29-S29 -> 0 | Z29: =+M29-T29 -> 0 | AA29: =+N29-U29 -> 0 | AB29: =+O29-V29 -> 0
D30: HPP | E30: CEV | F30: TL | H30: HPP | I30: 288 | J30: 3470000 | K30: 3470000 | L30: 2653747 | M30: 2653747 | N30: =J30+L30 -> 6123747 | O30: =K30+M30 -> 6123747 | Q30: 3470000 | R30: 3470000 | S30: 2653747.2 | T30: 2653747.2 | U30: 6123747.2 | V30: 6123747.2 | W30: =+J30-Q30 -> 0 | X30: =+K30-R30 -> 0 | Y30: =+L30-S30 -> -0.2 | Z30: =+M30-T30 -> -0.2 | AA30: =+N30-U30 -> -0.2 | AB30: =+O30-V30 -> -0.2
D31: HPP | E31: CEV | F31: TS | H31: HPP | I31: 276 | J31: 3430000 | K31: 3430000 | L31: 2543174 | M31: 2543174 | N31: =J31+L31 -> 5973174 | O31: =K31+M31 -> 5973174 | Q31: 3430000 | R31: 3430000 | S31: 2543174.4 | T31: 2543174.4 | U31: 5973174.4 | V31: 5973174.4 | W31: =+J31-Q31 -> 0 | X31: =+K31-R31 -> 0 | Y31: =+L31-S31 -> -0.4 | Z31: =+M31-T31 -> -0.4 | AA31: =+N31-U31 -> -0.4 | AB31: =+O31-V31 -> -0.4
D32: HPP | E32: VSIP | H32: HPP | I32: 246 | J32: 3070000 | K32: 3070000 | L32: 2266742 | M32: 2266742 | N32: =J32+L32 -> 5336742 | O32: =K32+M32 -> 5336742 | Q32: 3070000 | R32: 3070000 | S32: 2266742.4 | T32: 2266742.4 | U32: 5336742.4 | V32: 5336742.4 | W32: =+J32-Q32 -> 0 | X32: =+K32-R32 -> 0 | Y32: =+L32-S32 -> -0.4 | Z32: =+M32-T32 -> -0.4 | AA32: =+N32-U32 -> -0.4 | AB32: =+O32-V32 -> -0.4
D33: HPP | E33: VSIP | F33: TS | H33: HPP | I33: 266 | J33: 3400000 | K33: 3400000 | L33: 2451030 | M33: 2451030 | N33: =J33+L33 -> 5851030 | O33: =K33+M33 -> 5851030 | Q33: 3400000 | R33: 3400000 | S33: 2451030.4 | T33: 2451030.4 | U33: 5851030.4 | V33: 5851030.4 | W33: =+J33-Q33 -> 0 | X33: =+K33-R33 -> 0 | Y33: =+L33-S33 -> -0.4 | Z33: =+M33-T33 -> -0.4 | AA33: =+N33-U33 -> -0.4 | AB33: =+O33-V33 -> -0.4
D34: HPP | E34: VSIP | F34: QV | H34: HPP | I34: 268 | J34: 3410000 | K34: 3410000 | L34: 2469459 | M34: 2469459 | N34: =J34+L34 -> 5879459 | O34: =K34+M34 -> 5879459 | Q34: 3410000 | R34: 3410000 | S34: 2469459.2 | T34: 2469459.2 | U34: 5879459.2 | V34: 5879459.2 | W34: =+J34-Q34 -> 0 | X34: =+K34-R34 -> 0 | Y34: =+L34-S34 -> -0.2 | Z34: =+M34-T34 -> -0.2 | AA34: =+N34-U34 -> -0.2 | AB34: =+O34-V34 -> -0.2
D35: HPP | E35: VSIP | F35: TS | G35: QV | H35: HPP | I35: 288 | J35: 3620000 | K35: 3620000 | L35: 2653747 | M35: 2653747 | N35: =J35+L35 -> 6273747 | O35: =K35+M35 -> 6273747 | Q35: 3620000 | R35: 3620000 | S35: 2653747.2 | T35: 2653747.2 | U35: 6273747.2 | V35: 6273747.2 | W35: =+J35-Q35 -> 0 | X35: =+K35-R35 -> 0 | Y35: =+L35-S35 -> -0.2 | Z35: =+M35-T35 -> -0.2 | AA35: =+N35-U35 -> -0.2 | AB35: =+O35-V35 -> -0.2
C36: Transportation 1 way of Import/Export | D36: ICDQV | E36: TL | H36: HPP | I36: 287 | J36: 3320000 | K36: 3320000 | L36: 2644533 | M36: 2644533 | N36: =J36+L36 -> 5964533 | O36: =K36+M36 -> 5964533 | Q36: 3320000 | R36: 3320000 | S36: 2644532.8 | T36: 2644532.8 | U36: 5964532.8 | V36: 5964532.8 | W36: =+J36-Q36 -> 0 | X36: =+K36-R36 -> 0 | Y36: =+L36-S36 -> 0.2 | Z36: =+M36-T36 -> 0.2 | AA36: =+N36-U36 -> 0.2 | AB36: =+O36-V36 -> 0.2
D37: ICDQV | E37: TS | H37: HPP | I37: 266 | J37: 3050000 | K37: 3050000 | L37: 2451030 | M37: 2451030 | N37: =J37+L37 -> 5501030 | O37: =K37+M37 -> 5501030 | Q37: 3050000 | R37: 3050000 | S37: 2451030.4 | T37: 2451030.4 | U37: 5501030.4 | V37: 5501030.4 | W37: =+J37-Q37 -> 0 | X37: =+K37-R37 -> 0 | Y37: =+L37-S37 -> -0.4 | Z37: =+M37-T37 -> -0.4 | AA37: =+N37-U37 -> -0.4 | AB37: =+O37-V37 -> -0.4
D38: ICDQV | E38: QV | H38: HPP | I38: 255 | J38: 3010000 | K38: 3010000 | L38: 2349672 | M38: 2349672 | N38: =J38+L38 -> 5359672 | O38: =K38+M38 -> 5359672 | Q38: 3010000 | R38: 3010000 | S38: 2349672 | T38: 2349672 | U38: 5359672 | V38: 5359672 | W38: =+J38-Q38 -> 0 | X38: =+K38-R38 -> 0 | Y38: =+L38-S38 -> 0 | Z38: =+M38-T38 -> 0 | AA38: =+N38-U38 -> 0 | AB38: =+O38-V38 -> 0
D39: ICDQV | E39: TL | F39: TS | H39: HPP | I39: 312 | J39: 3800000 | K39: 3800000 | L39: 2874893 | M39: 2874893 | N39: =J39+L39 -> 6674893 | O39: =K39+M39 -> 6674893 | Q39: 3800000 | R39: 3800000 | S39: 2874892.8 | T39: 2874892.8 | U39: 6674892.8 | V39: 6674892.8 | W39: =+J39-Q39 -> 0 | X39: =+K39-R39 -> 0 | Y39: =+L39-S39 -> 0.2 | Z39: =+M39-T39 -> 0.2 | AA39: =+N39-U39 -> 0.2 | AB39: =+O39-V39 -> 0.2
D40: ICDQV | E40: TL | F40: QV | H40: HPP | I40: 320 | J40: 3820000 | K40: 3820000 | L40: 2948608 | M40: 2948608 | N40: =J40+L40 -> 6768608 | O40: =K40+M40 -> 6768608 | Q40: 3820000 | R40: 3820000 | S40: 2948608 | T40: 2948608 | U40: 6768608 | V40: 6768608 | W40: =+J40-Q40 -> 0 | X40: =+K40-R40 -> 0 | Y40: =+L40-S40 -> 0 | Z40: =+M40-T40 -> 0 | AA40: =+N40-U40 -> 0 | AB40: =+O40-V40 -> 0
D41: ICDQV | E41: TS | F41: QV | H41: HPP | I41: 280 | J41: 3390000 | K41: 3390000 | L41: 2580032 | M41: 2580032 | N41: =J41+L41 -> 5970032 | O41: =K41+M41 -> 5970032 | Q41: 3390000 | R41: 3390000 | S41: 2580032 | T41: 2580032 | U41: 5970032 | V41: 5970032 | W41: =+J41-Q41 -> 0 | X41: =+K41-R41 -> 0 | Y41: =+L41-S41 -> 0 | Z41: =+M41-T41 -> 0 | AA41: =+N41-U41 -> 0 | AB41: =+O41-V41 -> 0
D42: ICDQV | E42: TL | F42: TS | G42: QV | H42: HPP | I42: 366 | J42: 4120000 | K42: 4120000 | L42: 3372470 | M42: 3372470 | N42: =J42+L42 -> 7492470 | O42: =K42+M42 -> 7492470 | Q42: 4120000 | R42: 4120000 | S42: 3372470.4 | T42: 3372470.4 | U42: 7492470.4 | V42: 7492470.4 | W42: =+J42-Q42 -> 0 | X42: =+K42-R42 -> 0 | Y42: =+L42-S42 -> -0.4 | Z42: =+M42-T42 -> -0.4 | AA42: =+N42-U42 -> -0.4 | AB42: =+O42-V42 -> -0.4
D43: ICDTP | E43: TL | H43: HPP | I43: 287 | J43: 3320000 | K43: 3320000 | L43: 2644533 | M43: 2644533 | N43: =J43+L43 -> 5964533 | O43: =K43+M43 -> 5964533 | Q43: 3320000 | R43: 3320000 | S43: 2644532.8 | T43: 2644532.8 | U43: 5964532.8 | V43: 5964532.8 | W43: =+J43-Q43 -> 0 | X43: =+K43-R43 -> 0 | Y43: =+L43-S43 -> 0.2 | Z43: =+M43-T43 -> 0.2 | AA43: =+N43-U43 -> 0.2 | AB43: =+O43-V43 -> 0.2
D44: ICDTP | E44: TS | H44: HPP | I44: 266 | J44: 3050000 | K44: 3050000 | L44: 2451030 | M44: 2451030 | N44: =J44+L44 -> 5501030 | O44: =K44+M44 -> 5501030 | Q44: 3050000 | R44: 3050000 | S44: 2451030.4 | T44: 2451030.4 | U44: 5501030.4 | V44: 5501030.4 | W44: =+J44-Q44 -> 0 | X44: =+K44-R44 -> 0 | Y44: =+L44-S44 -> -0.4 | Z44: =+M44-T44 -> -0.4 | AA44: =+N44-U44 -> -0.4 | AB44: =+O44-V44 -> -0.4
...
