Workbook

Sheet COVER DN XUẤT
A1: CỘNG HÒA XÃ HỘI CHỦ NGHĨA VIỆT NAM
A2: Độc lập - Tự do - Hạnh Phúc
A4: DEBIT NOTE
A6: Căn cứ vào tình hình thực tế thực hiện,
A7: Chúng tôi gồm:
A8: BÊN MUA: CÔNG TY TNHH CANON VIỆT NAM - CHI NHÁNH TIÊN SƠN
A9: Địa chỉ: Số 12, đường TS10, Khu công nghiệp Tiên Sơn, Xã Đại Đồng, Tỉnh Bắc Ninh, Việt Nam
A10: MST: 0101125340002
A11: Đại diện: | D11: Chức vụ:
A13: BÊN BÁN: CÔNG TY CỔ PHẦN MBF
A14: Địa chỉ: Số 58 Xóm Giếng, Thôn Cổ Điển A, Xã Thanh Trì, Thành phố Hà Nội, Việt Nam
A15: MST: 0105040296
A16: Đại diện: | D16: Chức vụ:
A17: Cùng đối chiếu như sau:
C18: Debit No.: | D18: MBF-CTS11022026-1
C19: Date | D19: 23/02/2026
A22: DESCRIPTION | E22: AMOUNT (VND) | F22: REMARK
A23: 1 | B23: Trucking charge(VND) | E23: ='XUẤT-HPH'!J68 -> 167079801
A24: 2 | B24: Detention fee ( VND) | E24: ='XUẤT-HPH'!K68 -> 0
A25: 2 | B25: Custom fee (VND) | E25: ='XUẤT-HPH'!N68 -> 4600000
A26: 3 | B26: Submit CD and no EIR ( VND) | E26: ='XUẤT-HPH'!L68 -> 0
A27: 4 | B27: Round use container fee ( VND) | E27: ='XUẤT-HPH'!M68 -> 0
A36: SUB TOTAL | E36: =E23+E25+E26+E27+E24+E28 -> 171679801
A37: VAT 0%
A38: TOTAL DEBIT | E38: =SUM(E36:E37) -> 171679801
D41: Ngày 23 tháng 02 năm 2026
D43: ĐẠI DIỆN BÊN BÁN

Sheet XUẤT-HPH
A1: CỘNG HÒA XÃ HỘI CHỦ NGHĨA VIỆT NAM
A2: Độc lập - Tự do - Hạnh Phúc
A4: STATEMENT ACCOUNT FOR EXPORT CUSTOM CLEARANCE AND TRANSPORTATION FEE
A6: Căn cứ vào tình hình thực tế thực hiện,
A7: Chúng tôi gồm:
A8: BÊN MUA: CÔNG TY TNHH CANON VIỆT NAM - CHI NHÁNH TIÊN SƠN
A9: Địa chỉ: Số 12, đường TS10, Khu công nghiệp Tiên Sơn, Xã Đại Đồng, Tỉnh Bắc Ninh, Việt Nam
A10: MST: 0101125340002
A11: Đại diện: | D11: Chức vụ:
A13: BÊN BÁN: CÔNG TY CỔ PHẦN MBF
A14: Địa chỉ: Số 58 Xóm Giếng, Thôn Cổ Điển A, Xã Thanh Trì, Thành phố Hà Nội, Việt Nam
A15: MST: 0105040296
A16: Đại diện: | D16: Chức vụ:
A17: Cùng đối chiếu như sau:
N18: Debit No.: | O18: ='COVER DN XUẤT'!D18 -> MBF-CTS11022026-1
N19: Date | O19: ='COVER DN XUẤT'!D19 -> 23/02/2026 | Y19: , | Z19: Cước vận chuyển | AA19: , số cont | AB19: , Biển kiểm soát :
A21: STT | B21: Tuyến vận chuyển | C21: Ngày vận chuyển | D21: BL/ BKG | E21: Tờ khai | F21: Loại Conts | G21: CVN Invoice no | H21: Số Conts | I21: Biển kiểm soát/ Số hiệu sà lan | J21: Cước vận chuyển (chưa VAT) | K21: Lưu ca | L21: Tờ khai không phơi | M21: Phí tái sử dụng container rỗng | N21: Phí thanh lý tờ khai | O21: Tổng tiền | P21: Ghi chú | T21: Pick | U21: Laden
A22: =ROW()-21 -> 1 | B22: =VLOOKUP(P22,'chuyển 26.12'!$O$5:$P$6000,2,0) -> Hải Phòng - Canon Tiên Sơn - Hải Phòng | C22: 46038 | D22: 237500707611 | E22: =VLOOKUP(H22,[1]Sheet1!$I$1:$Q$180000,9,0) -> 308158278210 | F22: 40HC | G22: VS-26/50066 | H22: EMCU8313605 | I22: 29H-81871 | J22: 3588286 | N22: 100000 | O22: =SUM(J22:N22) -> 3688286 | P22: Lấy HPH - TS EX - Hạ HPH Disconnect | R22: Cont40 | T22: GIC | U22: GIC | Z22: =$Z$19&B22&$AA$19&H22 -> Cước vận chuyển Hải Phòng - Canon Tiên Sơn - Hải Phòng , số cont EMCU8313605
A23: =ROW()-21 -> 2 | B23: =VLOOKUP(P23,'chuyển 26.12'!$O$5:$P$6000,2,0) -> Hải Phòng - Canon Tiên Sơn - Hải Phòng | C23: 46038 | D23: HPH26A00675 | E23: =VLOOKUP(H23,[1]Sheet1!$I$1:$Q$180000,9,0) -> 308158323820 | F23: 40HC | G23: VF-26/50009 | H23: NSSU7171637 | I23: 29E-38441 | J23: 3888286 | N23: 100000 | O23: =SUM(J23:N23) -> 3988286 | P23: Lấy HPH - TS EX - Hạ HPH Connect | Q23: BB | R23: Cont40 | T23: GIC | U23: VIP GREEN PORT | Z23: =$Z$19&B23&$AA$19&H23 -> Cước vận chuyển Hải Phòng - Canon Tiên Sơn - Hải Phòng , số cont NSSU7171637
A24: =ROW()-21 -> 3 | B24: =VLOOKUP(P24,'chuyển 26.12'!$O$5:$P$6000,2,0) -> Hải Phòng - Canon Tiên Sơn - Hải Phòng | C24: 46038 | D24: 237500707611 | E24: =VLOOKUP(H24,[1]Sheet1!$I$1:$Q$180000,9,0) -> 308158430550 | F24: 40HC | G24: VS-26/50065 | H24: BMOU6012145 | I24: 29H-81743 | J24: 3588286 | N24: 100000 | O24: =SUM(J24:N24) -> 3688286 | P24: Lấy HPH - TS EX - Hạ HPH Disconnect | R24: Cont40 | T24: GIC | U24: GIC | Z24: =$Z$19&B24&$AA$19&H24 -> Cước vận chuyển Hải Phòng - Canon Tiên Sơn - Hải Phòng , số cont BMOU6012145
A25: =ROW()-21 -> 4 | B25: =VLOOKUP(P25,'chuyển 26.12'!$O$5:$P$6000,2,0) -> Hải Phòng - Canon Tiên Sơn - Hải Phòng | C25: 46038 | D25: 237500707611 | E25: =VLOOKUP(H25,[1]Sheet1!$I$1:$Q$180000,9,0) -> 308158509650 | F25: 40HC | G25: VS-26/50067 | H25: EGSU9553960 | I25: 29E-28914 | J25: 3888286 | N25: 100000 | O25: =SUM(J25:N25) -> 3988286 | P25: Lấy HPH - TS EX - Hạ HPH Connect | Q25: BB | R25: Cont40 | T25: GIC | U25: GIC | Z25: =$Z$19&B25&$AA$19&H25 -> Cước vận chuyển Hải Phòng - Canon Tiên Sơn - Hải Phòng , số cont EGSU9553960
A26: =ROW()-21 -> 5 | B26: =VLOOKUP(P26,'chuyển 26.12'!$O$5:$P$6000,2,0) -> Hưng Yên - Canon Tiên Sơn - Hải Phòng | C26: 46038 | D26: SGN2987352 | E26: =VLOOKUP(H26,[1]Sheet1!$I$1:$Q$180000,9,0) -> 308158360000 | F26: 40HC | G26: VH-26/50087 | H26: TRHU5424799 | I26: 15H-05911 | J26: 2985312 | N26: 100000 | O26: =SUM(J26:N26) -> 3085312 | P26: Lấy Hưng Yên - RU TS EX - Hạ HPH | R26: Cont40 | T26: RU HY | U26: TÂN VŨ | Z26: =$Z$19&B26&$AA$19&H26 -> Cước vận chuyển Hưng Yên - Canon Tiên Sơn - Hải Phòng , số cont TRHU5424799
A27: =ROW()-21 -> 6 | B27: =VLOOKUP(P27,'chuyển 26.12'!$O$5:$P$6000,2,0) -> Hưng Yên - Canon Tiên Sơn - Hải Phòng | C27: 46038 | D27: SGN2991014 | E27: =VLOOKUP(H27,[1]Sheet1!$I$1:$Q$180000,9,0) -> 308158391130 | F27: 40HC | G27: VH-26/50089 | H27: TCNU7535165 | I27: 15H-18666 | J27: 2985312 | N27: 100000 | O27: =SUM(J27:N27) -> 3085312 | P27: Lấy Hưng Yên - RU TS EX - Hạ HPH | R27: Cont40 | T27: RU HY | U27: TÂN VŨ | Z27: =$Z$19&B27&$AA$19&H27 -> Cước vận chuyển Hưng Yên - Canon Tiên Sơn - Hải Phòng , số cont TCNU7535165
A28: =ROW()-21 -> 7 | B28: =VLOOKUP(P28,'chuyển 26.12'!$O$5:$P$6000,2,0) -> Hải Phòng - Canon Tiên Sơn - Hải Phòng | C28: 46041 | D28: BHAIC26000188 | E28: =VLOOKUP(H28,[1]Sheet1!$I$1:$Q$180000,9,0) -> 308163768160 | F28: 40HC | G28: VS-26/50079 | H28: REGU5201120 | I28: 29E-28922 | J28: 3888286 | N28: 100000 | O28: =SUM(J28:N28) -> 3988286 | P28: Lấy HPH - TS EX - Hạ HPH Connect | Q28: BB | R28: Cont40 | T28: NAM HẢI ICD | U28: NAM HẢI ICD | Z28: =$Z$19&B28&$AA$19&H28 -> Cước vận chuyển Hải Phòng - Canon Tiên Sơn - Hải Phòng , số cont REGU5201120
A29: =ROW()-21 -> 8 | B29: =VLOOKUP(P29,'chuyển 26.12'!$O$5:$P$6000,2,0) -> Canon Tiên Sơn - Hải Phòng | C29: 46041 | D29: 6438798511 | E29: =VLOOKUP(H29,[1]Sheet1!$I$1:$Q$180000,9,0) -> 308163870250 | F29: 40HC | G29: VS-26/50074 | H29: TIIU5347234 | I29: 29H-81846 | J29: 2697592 | N29: 100000 | O29: =SUM(J29:N29) -> 2797592 | P29: Lấy HPH - TS IM - RU TS EX - Hạ HPH | R29: Cont40 | T29: RU CTS | U29: TÂN VŨ | Z29: =$Z$19&B29&$AA$19&H29 -> Cước vận chuyển Canon Tiên Sơn - Hải Phòng , số cont TIIU5347234
A30: =ROW()-21 -> 9 | B30: =VLOOKUP(P30,'chuyển 26.12'!$O$5:$P$6000,2,0) -> Hưng Yên - Canon Tiên Sơn - Hải Phòng | C30: 46042 | D30: 6438798511 | E30: =VLOOKUP(H30,[1]Sheet1!$I$1:$Q$180000,9,0) -> 308169652730 | F30: 40HC | G30: VS-26/50089 | H30: CSNU8639981 | I30: 15C-02338 | J30: 2985312 | N30: 100000 | O30: =SUM(J30:N30) -> 3085312 | P30: Lấy Hưng Yên - RU TS EX - Hạ HPH | R30: Cont40 | T30: RU HY | U30: TÂN VŨ | Z30: =$Z$19&B30&$AA$19&H30 -> Cước vận chuyển Hưng Yên - Canon Tiên Sơn - Hải Phòng , số cont CSNU8639981
A31: =ROW()-21 -> 10 | B31: =VLOOKUP(P31,'chuyển 26.12'!$O$5:$P$6000,2,0) -> Hải Phòng - Canon Tiên Sơn - Hải Phòng | C31: 46043 | D31: 237600063367 | E31: 308173905600 | F31: 20DC | G31: VH-26/50108 | H31: EITU3162502 | I31: 29E-38441 | J31: 3588286 | N31: 100000 | O31: =SUM(J31:N31) -> 3688286 | P31: Lấy HPH - TS EX - Hạ HPH Disconnect | R31: Cont20 | T31: CHÂN THẬT | U31: GIC | Z31: =$Z$19&B31&$AA$19&H31 -> Cước vận chuyển Hải Phòng - Canon Tiên Sơn - Hải Phòng , số cont EITU3162502
A32: =ROW()-21 -> 11 | B32: =VLOOKUP(P32,'chuyển 26.12'!$O$5:$P$6000,2,0) -> Hải Phòng - Canon Tiên Sơn - Hải Phòng | C32: 46045 | D32: 237500733123 | E32: =VLOOKUP(H32,[1]Sheet1!$I$1:$Q$180000,9,0) -> 308182232540 | F32: 40HC | G32: VH-26/50120 | H32: EGSU6484249 | I32: 29E-38562 | J32: 3588286 | N32: 100000 | O32: =SUM(J32:N32) -> 3688286 | P32: Lấy HPH - TS EX - Hạ HPH Disconnect | R32: Cont40 | T32: GIC | U32: GIC | Z32: =$Z$19&B32&$AA$19&H32 -> Cước vận chuyển Hải Phòng - Canon Tiên Sơn - Hải Phòng , số cont EGSU6484249
A33: =ROW()-21 -> 12 | B33: =VLOOKUP(P33,'chuyển 26.12'!$O$5:$P$6000,2,0) -> Hải Phòng - Canon Tiên Sơn - Hải Phòng | C33: 46045 | D33: 237500736122 | E33: =VLOOKUP(H33,[1]Sheet1!$I$1:$Q$180000,9,0) -> 308181125140 | F33: 40HC | G33: VS-26/50113 | H33: TGBU6583045 | I33: 29H-81743 | J33: 3888286 | N33: 100000 | O33: =SUM(J33:N33) -> 3988286 | P33: Lấy HPH - TS EX - Hạ HPH Connect | Q33: BB | R33: Cont40 | T33: GFORTUNE | U33: GIC | Z33: =$Z$19&B33&$AA$19&H33 -> Cước vận chuyển Hải Phòng - Canon Tiên Sơn - Hải Phòng , số cont TGBU6583045
A34: =ROW()-21 -> 13 | B34: =VLOOKUP(P34,'chuyển 26.12'!$O$5:$P$6000,2,0) -> Hải Phòng - Canon Tiên Sơn - Hải Phòng | C34: 46045 | D34: 237500737447 | E34: =VLOOKUP(H34,[1]Sheet1!$I$1:$Q$180000,9,0) -> 308182479050 | F34: 40HC | G34: VS-26/50107 | H34: EGHU9330270 | I34: 29E-38441 | J34: 3588286 | N34: 100000 | O34: =SUM(J34:N34) -> 3688286 | P34: Lấy HPH - TS EX - Hạ HPH Disconnect | R34: Cont40 | T34: GFORTUNE | U34: GIC | Z34: =$Z$19&B34&$AA$19&H34 -> Cước vận chuyển Hải Phòng - Canon Tiên Sơn - Hải Phòng , số cont EGHU9330270
A35: =ROW()-21 -> 14 | B35: =VLOOKUP(P35,'chuyển 26.12'!$O$5:$P$6000,2,0) -> Hải Phòng - Canon Tiên Sơn - Hải Phòng | C35: 46046 | D35: 237500737447 | E35: =VLOOKUP(H35,[1]Sheet1!$I$1:$Q$180000,9,0) -> 308184601230 | F35: 40HC | G35: VS-26/50115 | H35: TIIU5457859 | I35: 29E-28922 | J35: 3588286 | N35: 100000 | O35: =SUM(J35:N35) -> 3688286 | P35: Lấy HPH - TS EX - Hạ HPH Disconnect | R35: Cont40 | T35: GFORTUNE | U35: GIC | Z35: =$Z$19&B35&$AA$19&H35 -> Cước vận chuyển Hải Phòng - Canon Tiên Sơn - Hải Phòng , số cont TIIU5457859
A36: =ROW()-21 -> 15 | B36: =VLOOKUP(P36,'chuyển 26.12'!$O$5:$P$6000,2,0) -> Hải Phòng - Canon Tiên Sơn - Hải Phòng | C36: 46046 | D36: 237500736122 | E36: =VLOOKUP(H36,[1]Sheet1!$I$1:$Q$180000,9,0) -> 308184642050 | F36: 40HC | G36: VS-26/50112 | H36: FFAU1594240 | I36: 29E-28914 | J36: 3588286 | N36: 100000 | O36: =SUM(J36:N36) -> 3688286 | P36: Lấy HPH - TS EX - Hạ HPH Disconnect | R36: Cont40 | T36: GFORTUNE | U36: GIC | Z36: =$Z$19&B36&$AA$19&H36 -> Cước vận chuyển Hải Phòng - Canon Tiên Sơn - Hải Phòng , số cont FFAU1594240
A37: =ROW()-21 -> 16 | B37: =VLOOKUP(P37,'chuyển 26.12'!$O$5:$P$6000,2,0) -> Hải Phòng - Canon Tiên Sơn - Hải Phòng | C37: 46046 | D37: 237500733123 | E37: =VLOOKUP(H37,[1]Sheet1!$I$1:$Q$180000,9,0) -> 308184728520 | F37: 40HC | G37: VH-26/50128 | H37: EGSU6484172 | I37: 29H-81871 | J37: 3888286 | N37: 100000 | O37: =SUM(J37:N37) -> 3988286 | P37: Lấy HPH - TS EX - Hạ HPH Connect | Q37: BB | R37: Cont40 | T37: GIC | U37: GIC | Z37: =$Z$19&B37&$AA$19&H37 -> Cước vận chuyển Hải Phòng - Canon Tiên Sơn - Hải Phòng , số cont EGSU6484172
A38: =ROW()-21 -> 17 | B38: =VLOOKUP(P38,'chuyển 26.12'!$O$5:$P$6000,2,0) -> Hải Phòng - Canon Tiên Sơn - Hải Phòng | C38: 46046 | D38: 237500733123 | E38: =VLOOKUP(H38,[1]Sheet1!$I$1:$Q$180000,9,0) -> 308184527510 | F38: 40HC | G38: VH-26/50129 | H38: EGSU6489718 | I38: 29H-81921 | J38: 3888286 | N38: 100000 | O38: =SUM(J38:N38) -> 3988286 | P38: Lấy HPH - TS EX - Hạ HPH Connect | Q38: BB | R38: Cont40 | T38: GIC | U38: GIC | Z38: =$Z$19&B38&$AA$19&H38 -> Cước vận chuyển Hải Phòng - Canon Tiên Sơn - Hải Phòng , số cont EGSU6489718
A39: =ROW()-21 -> 18 | B39: =VLOOKUP(P39,'chuyển 26.12'!$O$5:$P$6000,2,0) -> Hải Phòng - Canon Tiên Sơn - Hải Phòng | C39: 46048 | D39: 237500736122 | E39: =VLOOKUP(H39,[1]Sheet1!$I$1:$Q$180000,9,0) -> 308188076360 | F39: 40HC | G39: VH-26/50138 | H39: EGHU9777247 | I39: 29H-88946 | J39: 3588286 | N39: 100000 | O39: =SUM(J39:N39) -> 3688286 | P39: Lấy HPH - TS EX - Hạ HPH Disconnect | R39: Cont40 | T39: GFORTUNE | U39: GIC | Z39: =$Z$19&B39&$AA$19&H39 -> Cước vận chuyển Hải Phòng - Canon Tiên Sơn - Hải Phòng , số cont EGHU9777247
A40: =ROW()-21 -> 19 | B40: =VLOOKUP(P40,'chuyển 26.12'!$O$5:$P$6000,2,0) -> Hải Phòng - Canon Tiên Sơn - Hải Phòng | C40: 46048 | D40: HANA57597700 | E40: =VLOOKUP(H40,[1]Sheet1!$I$1:$Q$180000,9,0) -> 308188091320 | F40: 40HC | G40: VS-26/50105 | H40: HMMU7026820 | I40: 29H-81607 | J40: 3588286 | N40: 100000 | O40: =SUM(J40:N40) -> 3688286 | P40: Lấy HPH - TS EX - Hạ HPH Disconnect | R40: Cont40 | T40: TÂN CẢNG 128 | U40: HÀ HƯNG HẢI | Z40: =$Z$19&B40&$AA$19&H40 -> Cước vận chuyển Hải Phòng - Canon Tiên Sơn - Hải Phòng , số cont HMMU7026820
A41: =ROW()-21 -> 20 | B41: =VLOOKUP(P41,'chuyển 26.12'!$O$5:$P$6000,2,0) -> Hải Phòng - Canon Tiên Sơn - Hải Phòng | C41: 46049 | D41: 237500733123 | E41: =VLOOKUP(H41,[1]Sheet1!$I$1:$Q$180000,9,0) -> 308193111610 | F41: 40HC | G41: VH-26/50144 | H41: GCXU6443400 | I41: 29E-28922 | J41: 3588286 | N41: 100000 | O41: =SUM(J41:N41) -> 3688286 | P41: Lấy HPH - TS EX - Hạ HPH Disconnect | R41: Cont40 | T41: GIC | U41: GIC | Z41: =$Z$19&B41&$AA$19&H41 -> Cước vận chuyển Hải Phòng - Canon Tiên Sơn - Hải Phòng , số cont GCXU6443400
A42: =ROW()-21 -> 21 | B42: =VLOOKUP(P42,'chuyển 26.12'!$O$5:$P$6000,2,0) -> Hải Phòng - Canon Tiên Sơn - Hải Phòng | C42: 46051 | D42: 237600097369 | E42: =VLOOKUP(H42,[1]Sheet1!$I$1:$Q$180000,9,0) -> 308202099500 | F42: 40HC | G42: VH-26/50156 | H42: EGSU1600794 | I42: 29H-81921 | J42: 3888286 | N42: 100000 | O42: =SUM(J42:N42) -> 3988286 | P42: Lấy HPH - TS EX - Hạ HPH Connect | Q42: BB | R42: Cont40 | T42: SAO Á | U42: GIC | Z42: =$Z$19&B42&$AA$19&H42 -> Cước vận chuyển Hải Phòng - Canon Tiên Sơn - Hải Phòng , số cont EGSU1600794
A43: =ROW()-21 -> 22 | B43: =VLOOKUP(P43,'chuyển 26.12'!$O$5:$P$6000,2,0) -> Hải Phòng - Canon Tiên Sơn - Hải Phòng | C43: 46051 | D43: 237600056956 | E43: =VLOOKUP(H43,[1]Sheet1!$I$1:$Q$180000,9,0) -> 308202123520 | F43: 40HC | G43: VS-26/50138 | H43: TLLU7977255 | I43: 29H-81846 | J43: 3888286 | N43: 100000 | O43: =SUM(J43:N43) -> 3988286 | P43: Lấy HPH - TS EX - Hạ HPH Connect | Q43: BB | R43: Cont40 | T43: GFORTUNE | U43: GIC | Z43: =$Z$19&B43&$AA$19&H43 -> Cước vận chuyển Hải Phòng - Canon Tiên Sơn - Hải Phòng , số cont TLLU7977255
A44: =ROW()-21 -> 23 | B44: =VLOOKUP(P44,'chuyển 26.12'!$O$5:$P$6000,2,0) -> Hưng Yên - Canon Tiên Sơn - Hải Phòng | C44: 46051 | D44: SGN3036238 | E44: 308202052820 | F44: 40HC | G44: VH-26/50157 | H44: CMAU7489161 | I44: 15C-16755 | J44: 2985312 | N44: 100000 | O44: =SUM(J44:N44) -> 3085312 | P44: Lấy Hưng Yên - RU TS EX - Hạ HPH | R44: Cont40 | T44: RU HY | U44: TÂN VŨ | Z44: =$Z$19&B44&$AA$19&H44 -> Cước vận chuyển Hưng Yên - Canon Tiên Sơn - Hải Phòng , số cont CMAU7489161
...

Sheet COVER DN ICDTP
A1: CỘNG HÒA XÃ HỘI CHỦ NGHĨA VIỆT NAM
A2: Độc lập - Tự do - Hạnh Phúc
A4: DEBIT NOTE
A6: Căn cứ vào tình hình thực tế thực hiện,
A7: Chúng tôi gồm:
A8: BÊN MUA: CÔNG TY TNHH CANON VIỆT NAM - CHI NHÁNH TIÊN SƠN
A9: Địa chỉ: Số 12, đường TS10, Khu công nghiệp Tiên Sơn, Xã Đại Đồng, Tỉnh Bắc Ninh, Việt Nam
A10: MST: 0101125340002
A11: Đại diện: | D11: Chức vụ:
A13: BÊN BÁN: CÔNG TY CỔ PHẦN MBF
A14: Địa chỉ: Số 58 Xóm Giếng, Thôn Cổ Điển A, Xã Thanh Trì, Thành phố Hà Nội, Việt Nam
A15: MST: 0105040296
A16: Đại diện: | D16: Chức vụ:
A17: Cùng đối chiếu như sau:
C18: Debit No.: | D18: MBF-CTS11022026-4
C19: Date | D19: ='COVER DN XUẤT'!D19 -> 23/02/2026
A22: DESCRIPTION | E22: AMOUNT (VND) | F22: REMARK
A23: 1 | B23: Trucking charge ICDTP - TS - ICD TP (VND) | E23: ='ICD TP'!K44 -> 29158670
A24: 2 | B24: Round use container fee ( VND) | E24: ='[2]XUẤT- ICD'!O100 -> 0
A25: 3 | B25: Barging fee ( VND ) | E25: ='ICD TP'!L44 -> 81000000
A26: 4 | B26: Custom fee (VND) | E26: ='ICD TP'!P44 -> 2100000
A27: 5 | B27: Submit CD + EIR overtime | E27: ='[2]XUẤT- ICD'!N100 -> 0
A28: 6 | B28: Detention fee | E28: ='[2]XUẤT- ICD'!Q100 -> 0
A29: 7 | B29: Trucking charge HPH - TS - HPH (VND) | E29: ='[2]XUẤT- ICD'!M100 -> 0
A30: 8 | B30: Transportation fee for truck comeback to ICD without Container | E30: ='ICD TP'!M44 -> 0
A35: SUB TOTAL | E35: =E23+E24+E25+E26+E27+E28+E29+E30 -> 112258670
A36: VAT 0%
A37: TOTAL DEBIT | E37: =SUM(E35:E36) -> 112258670
D40: ='COVER DN XUẤT'!D41 -> Ngày 23 tháng 02 năm 2026
D42: ĐẠI DIỆN BÊN BÁN

Sheet ICD TP
A1: CỘNG HÒA XÃ HỘI CHỦ NGHĨA VIỆT NAM
A2: Độc lập - Tự do - Hạnh Phúc
A4: STATEMENT ACCOUNT FOR EXPORT CUSTOM CLEARANCE AND TRANSPORTATION FEE
A6: Căn cứ vào tình hình thực tế thực hiện,
A7: Chúng tôi gồm:
A8: BÊN MUA: CÔNG TY TNHH CANON VIỆT NAM - CHI NHÁNH TIÊN SƠN
A9: Địa chỉ: Số 12, đường TS10, Khu công nghiệp Tiên Sơn, Xã Đại Đồng, Tỉnh Bắc Ninh, Việt Nam
A10: MST: 0101125340002
A11: Đại diện: | D11: Chức vụ:
A13: BÊN BÁN: CÔNG TY CỔ PHẦN MBF | U13: Cước vận chuyển nội địa Tiên Sơn- ICD Tri Phương | V13: TP - TS EX - TP + sà lan
A14: Địa chỉ: Số 58 Xóm Giếng, Thôn Cổ Điển A, Xã Thanh Trì, Thành phố Hà Nội, Việt Nam
A15: MST: 0105040296
A16: Đại diện: | D16: Chức vụ:
A17: Cùng đối chiếu như sau:
P18: Debit No.: | R18: ='COVER DN ICDTP'!D18 -> MBF-CTS11022026-4 | AD18: Cước vận chuyển sà lan
P19: Date | R19: ='COVER DN ICDTP'!D19 -> 23/02/2026 | AC19: ICD Tri Phương- Canon Tiên Sơn- ICD Tri Phương | AD19: ICD Tri Phương - Lạch Huyện, Hải Phòng
A21: STT | B21: Tuyến vận chuyển | C21: Ngày vận chuyển | D21: BL/ BKG | E21: Tờ khai | F21: Loại Conts | G21: CVN Invoice no | H21: Số Conts | I21: Biển kiểm soát | J21: Số hiệu sà lan | K21: Cước vận chuyển | L21: Cước vận chuyển sà lan ICD Tri Phương - HPH | M21: Phí vận tải đi đầu không | N21: Phí thanh lý tờ khai ngoài giờ | O21: Phí tái sử dụng container rỗng | P21: Phí thanh lý tờ khai | Q21: Phí lưu ca | R21: Tổng tiền | S21: Ghi chú | V21: Sà Lan Hạ | X21: Cont vào | Y21: Cont ra | Z21: , | AC21: Cước vận chuyển | AD21: , số cont | AF21: , Số hiệu sà lan :
A22: =ROW()-21 -> 1 | B22: ICD Tri Phương- Canon Tiên Sơn- ICD Tri Phương | C22: 46039 | D22: 6438798510 | F22: 40HC | G22: VH-26/50088 | H22: FFAU2878148 | I22: 29K-12627 | K22: 1478840 | R22: =SUM(K22:Q22) -> 1478840 | T22: BB | AC22: =$AC$21&$AC$19&$AD$21&H22 -> Cước vận chuyển ICD Tri Phương- Canon Tiên Sơn- ICD Tri Phương , số cont FFAU2878148
A23: =ROW()-21 -> 2 | B23: ICD Tri Phương- Canon Tiên Sơn- ICD Tri Phương - sà lan Lạch Huyện, Hải Phòng | C23: 46039 | D23: 262590698 | E23: 308161200230 | F23: 40HC | G23: VS-26/50072 | H23: TCNU8079500 | I23: 29H-86407 | J23: SOWATCO 05 (BN-2605) | K23: 1178840 | L23: 4050000 | P23: 100000 | R23: =SUM(K23:Q23) -> 5328840 | AC23: =$AC$21&$AC$19&$AD$21&H23 -> Cước vận chuyển ICD Tri Phương- Canon Tiên Sơn- ICD Tri Phương , số cont TCNU8079500 | AD23: =$AD$18&$AD$19&$AD$21&H23 -> Cước vận chuyển sà lan ICD Tri Phương - Lạch Huyện, Hải Phòng , số cont TCNU8079500
A24: =ROW()-21 -> 3 | B24: ICD Tri Phương- Canon Tiên Sơn- ICD Tri Phương - sà lan Lạch Huyện, Hải Phòng | C24: 46039 | D24: 262590698 | E24: 308161249010 | F24: 40HC | G24: VS-26/50073 | H24: HASU4792005 | I24: 29C-18195 | J24: SOWATCO 05 (BN-2605) | K24: 1178840 | L24: 4050000 | P24: 100000 | R24: =SUM(K24:Q24) -> 5328840 | AC24: =$AC$21&$AC$19&$AD$21&H24 -> Cước vận chuyển ICD Tri Phương- Canon Tiên Sơn- ICD Tri Phương , số cont HASU4792005 | AD24: =$AD$18&$AD$19&$AD$21&H24 -> Cước vận chuyển sà lan ICD Tri Phương - Lạch Huyện, Hải Phòng , số cont HASU4792005
A25: =ROW()-21 -> 4 | B25: ICD Tri Phương- Canon Tiên Sơn- ICD Tri Phương - sà lan Lạch Huyện, Hải Phòng | C25: 46043 | D25: 262863213 | E25: 308174416450 | F25: 40HC | G25: VS-26/50090 | H25: UETU6938394 | I25: 29H-86407 | J25: SOWATCO 03 (BN-2603) | K25: 1178840 | L25: 4050000 | P25: 100000 | R25: =SUM(K25:Q25) -> 5328840 | AC25: =$AC$21&$AC$19&$AD$21&H25 -> Cước vận chuyển ICD Tri Phương- Canon Tiên Sơn- ICD Tri Phương , số cont UETU6938394 | AD25: =$AD$18&$AD$19&$AD$21&H25 -> Cước vận chuyển sà lan ICD Tri Phương - Lạch Huyện, Hải Phòng , số cont UETU6938394
A26: =ROW()-21 -> 5 | B26: ICD Tri Phương- Canon Tiên Sơn- ICD Tri Phương - sà lan Lạch Huyện, Hải Phòng | C26: 46045 | D26: 262863213 | E26: 308182398000 | F26: 40HC | G26: VS-26/50111 | H26: MRSU7085290 | I26: 29H-88946 | J26: SOWATCO 02 (BN-2602) | K26: 1178840 | L26: 4050000 | P26: 100000 | R26: =SUM(K26:Q26) -> 5328840 | AC26: =$AC$21&$AC$19&$AD$21&H26 -> Cước vận chuyển ICD Tri Phương- Canon Tiên Sơn- ICD Tri Phương , số cont MRSU7085290 | AD26: =$AD$18&$AD$19&$AD$21&H26 -> Cước vận chuyển sà lan ICD Tri Phương - Lạch Huyện, Hải Phòng , số cont MRSU7085290
A27: =ROW()-21 -> 6 | B27: ICD Tri Phương- Canon Tiên Sơn- ICD Tri Phương - sà lan Lạch Huyện, Hải Phòng | C27: 46049 | D27: 263155880 | E27: 308196593520 | F27: 40HC | G27: VS-26/50130 | H27: MRKU6092501 | I27: 29K-12627 | J27: SOWATCO 03 (BN-2603) | K27: 1178840 | L27: 4050000 | P27: 100000 | R27: =SUM(K27:Q27) -> 5328840 | AC27: =$AC$21&$AC$19&$AD$21&H27 -> Cước vận chuyển ICD Tri Phương- Canon Tiên Sơn- ICD Tri Phương , số cont MRKU6092501 | AD27: =$AD$18&$AD$19&$AD$21&H27 -> Cước vận chuyển sà lan ICD Tri Phương - Lạch Huyện, Hải Phòng , số cont MRKU6092501
A28: =ROW()-21 -> 7 | B28: ICD Tri Phương- Canon Tiên Sơn- ICD Tri Phương - sà lan Lạch Huyện, Hải Phòng | C28: 46050 | D28: 263155880 | E28: 308201614950 | F28: 40HC | G28: VS-26/50127 | H28: CAIU8271361 | I28: 29H-86403 | J28: SOWATCO 01 (BN-2601) | K28: 1178840 | L28: 4050000 | P28: 100000 | R28: =SUM(K28:Q28) -> 5328840 | AC28: =$AC$21&$AC$19&$AD$21&H28 -> Cước vận chuyển ICD Tri Phương- Canon Tiên Sơn- ICD Tri Phương , số cont CAIU8271361 | AD28: =$AD$18&$AD$19&$AD$21&H28 -> Cước vận chuyển sà lan ICD Tri Phương - Lạch Huyện, Hải Phòng , số cont CAIU8271361
A29: =ROW()-21 -> 8 | B29: ICD Tri Phương- Canon Tiên Sơn- ICD Tri Phương - sà lan Lạch Huyện, Hải Phòng | C29: 46050 | D29: 263155880 | E29: 308202089550 | F29: 40HC | G29: VS-26/50126 | H29: MRKU4878425 | I29: 29C-18195 | J29: SOWATCO 01 (BN-2601) | K29: 1178840 | L29: 4050000 | P29: 100000 | R29: =SUM(K29:Q29) -> 5328840 | AC29: =$AC$21&$AC$19&$AD$21&H29 -> Cước vận chuyển ICD Tri Phương- Canon Tiên Sơn- ICD Tri Phương , số cont MRKU4878425 | AD29: =$AD$18&$AD$19&$AD$21&H29 -> Cước vận chuyển sà lan ICD Tri Phương - Lạch Huyện, Hải Phòng , số cont MRKU4878425
A30: =ROW()-21 -> 9 | B30: ICD Tri Phương- Canon Tiên Sơn- ICD Tri Phương - sà lan Lạch Huyện, Hải Phòng | C30: 46052 | D30: 263415697 | E30: 308214657940 | F30: 40HC | G30: VS-26/50149 | H30: MRKU5471706 | I30: 29C-18195 | J30: SOWATCO 01 (BN-2601) | K30: 1194380 | L30: 4050000 | P30: 100000 | R30: =SUM(K30:Q30) -> 5344380 | AC30: =$AC$21&$AC$19&$AD$21&H30 -> Cước vận chuyển ICD Tri Phương- Canon Tiên Sơn- ICD Tri Phương , số cont MRKU5471706 | AD30: =$AD$18&$AD$19&$AD$21&H30 -> Cước vận chuyển sà lan ICD Tri Phương - Lạch Huyện, Hải Phòng , số cont MRKU5471706
A31: =ROW()-21 -> 10 | B31: ICD Tri Phương- Canon Tiên Sơn- ICD Tri Phương - sà lan Lạch Huyện, Hải Phòng | C31: 46055 | D31: 263415697 | E31: 308214658640 | F31: 40HC | G31: VS-26/50150 | H31: MRKU5130187 | I31: 29H-88946 | J31: SOWATCO 01 (BN-2601) | K31: 1194380 | L31: 4050000 | P31: 100000 | R31: =SUM(K31:Q31) -> 5344380 | AC31: =$AC$21&$AC$19&$AD$21&H31 -> Cước vận chuyển ICD Tri Phương- Canon Tiên Sơn- ICD Tri Phương , số cont MRKU5130187 | AD31: =$AD$18&$AD$19&$AD$21&H31 -> Cước vận chuyển sà lan ICD Tri Phương - Lạch Huyện, Hải Phòng , số cont MRKU5130187
A32: =ROW()-21 -> 11 | B32: ICD Tri Phương- Canon Tiên Sơn- ICD Tri Phương - sà lan Lạch Huyện, Hải Phòng | C32: 46055 | D32: 263415697 | E32: 308214659120 | F32: 40HC | G32: VS-26/50151 | H32: MRSU3560345 | I32: 29K-12627 | J32: SOWATCO 01 (BN-2601) | K32: 1194380 | L32: 4050000 | P32: 100000 | R32: =SUM(K32:Q32) -> 5344380 | AC32: =$AC$21&$AC$19&$AD$21&H32 -> Cước vận chuyển ICD Tri Phương- Canon Tiên Sơn- ICD Tri Phương , số cont MRSU3560345 | AD32: =$AD$18&$AD$19&$AD$21&H32 -> Cước vận chuyển sà lan ICD Tri Phương - Lạch Huyện, Hải Phòng , số cont MRSU3560345
A33: =ROW()-21 -> 12 | B33: ICD Tri Phương- Canon Tiên Sơn- ICD Tri Phương - sà lan Lạch Huyện, Hải Phòng | C33: 46055 | D33: 263415697 | E33: 308214659600 | F33: 40HC | G33: VS-26/50153 | H33: CAAU5939840 | I33: 29E-38583 | J33: SOWATCO 01 (BN-2601) | K33: 1194380 | L33: 4050000 | P33: 100000 | R33: =SUM(K33:Q33) -> 5344380 | AC33: =$AC$21&$AC$19&$AD$21&H33 -> Cước vận chuyển ICD Tri Phương- Canon Tiên Sơn- ICD Tri Phương , số cont CAAU5939840 | AD33: =$AD$18&$AD$19&$AD$21&H33 -> Cước vận chuyển sà lan ICD Tri Phương - Lạch Huyện, Hải Phòng , số cont CAAU5939840
A34: =ROW()-21 -> 13 | B34: ICD Tri Phương- Canon Tiên Sơn- ICD Tri Phương - sà lan Lạch Huyện, Hải Phòng | C34: 46056 | D34: 263415697 | E34: 308219941650 | F34: 40HC | G34: VS-26/50158 | H34: GESU6907082 | I34: 29H-88946 | J34: SOWATCO 01 (BN-2601) | K34: 1194380 | L34: 4050000 | P34: 100000 | R34: =SUM(K34:Q34) -> 5344380 | AC34: =$AC$21&$AC$19&$AD$21&H34 -> Cước vận chuyển ICD Tri Phương- Canon Tiên Sơn- ICD Tri Phương , số cont GESU6907082 | AD34: =$AD$18&$AD$19&$AD$21&H34 -> Cước vận chuyển sà lan ICD Tri Phương - Lạch Huyện, Hải Phòng , số cont GESU6907082
... A42: =ROW()-21 -> 21 | B42: ICD Tri Phương- Canon Tiên Sơn- ICD Tri Phương - sà lan Lạch Huyện, Hải Phòng | C42: 46064 | D42: 263587242 | E42: 308252746230 | F42: 40HC | G42: VS-26/50211 | H42: MRKU4366054 | I42: 29C-18195 | J42: SOWATCO 02 (BN-2602) | K42: 1194380 | L42: 4050000 | P42: 100000 | R42: =SUM(K42:Q42) -> 5344380 | AC42: =$AC$21&$AC$19&$AD$21&H42 -> Cước vận chuyển ICD Tri Phương- Canon Tiên Sơn- ICD Tri Phương , số cont MRKU4366054 | AD42: =$AD$18&$AD$19&$AD$21&H42 -> Cước vận chuyển sà lan ICD Tri Phương - Lạch Huyện, Hải Phòng , số cont MRKU4366054
A43: =ROW()-21 -> 22 | B43: ICD Tri Phương- Canon Tiên Sơn- Lạch Huyện, Hải Phòng | C43: 46046 | D43: 262863213 | E43: 308184475600 | F43: 40HC | G43: VS-26/50116 | H43: MRSU3059225 | I43: 29H-88946 | K43: 3901010 | P43: 100000 | R43: =SUM(K43:Q43) -> 4001010 | AC43: Cước vận chuyển ICD Tri Phương- Canon Tiên Sơn- Lạch Huyện, Hải Phòng , số cont MRSU3059225
A44: Tổng | K44: =SUM(K22:K43) -> 29158670 | L44: =SUM(L22:L43) -> 81000000 | M44: =SUM(M22:M43) -> 0 | N44: =SUM(N22:N41) -> 0 | O44: =SUM(O22:O41) -> 0 | P44: =SUM(P22:P43) -> 2100000 | Q44: =SUM(Q22:Q41) -> 0 | R44: =SUM(R22:R43) -> 112258670
K46: ='COVER DN ICDTP'!D40 -> Ngày 23 tháng 02 năm 2026
K48: ĐẠI DIỆN BÊN BÁN

Sheet chuyển 26.12
O5: Lấy HPH - TS IM - RU TS EX - Hạ Lạch Huyện | P5: Canon Tiên Sơn - Lạch Huyện, Hải Phòng
O6: Lấy HPH - TS EX - Hạ HPH | P6: Hải Phòng - Canon Tiên Sơn - Hải Phòng
O7: Lấy HPH - TS EX - Hạ HPH Connect | P7: Hải Phòng - Canon Tiên Sơn - Hải Phòng
O8: Lấy Hưng Yên - RU TS EX - Hạ HPH | P8: Hưng Yên - Canon Tiên Sơn - Hải Phòng
O9: Lấy Hưng Yên - RU TS EX - Hạ HPH | P9: Hưng Yên - Canon Tiên Sơn - Hải Phòng
O10: Lấy Hưng Yên - RU TS EX - Hạ HPH | P10: Hưng Yên - Canon Tiên Sơn - Hải Phòng
O11: Lấy Hưng Yên - RU TS EX - Hạ HPH | P11: Hưng Yên - Canon Tiên Sơn - Hải Phòng
O12: Lấy HPH - TS EX - Hạ HPH | P12: Hải Phòng - Canon Tiên Sơn - Hải Phòng
O13: Lấy HPH - TS EX - Hạ HPH | P13: Hải Phòng - Canon Tiên Sơn - Hải Phòng
O14: Lấy HPH - Trả nhập 2 điểm TL , TS - RU TS EX - Hạ Lạch Huyện | P14: Canon Tiên Sơn - Lạch Huyện, Hải Phòng
O15: Lấy HPH - TS EX - Hạ HPH | P15: Hải Phòng - Canon Tiên Sơn - Hải Phòng
O16: Lấy HPH - TS IM - RU TS EX - Hạ Lạch Huyện | P16: Canon Tiên Sơn - Lạch Huyện, Hải Phòng
... O42: Lấy Lạch Huyện - TS EX - Hạ HPH Disconnect | P42: Lạch Huyện - Canon Tiên Sơn - Hải Phòng

Sheet COVER BTB XUẤT
A1: CỘNG HÒA XÃ HỘI CHỦ NGHĨA VIỆT NAM
A2: Độc lập - Tự do - Hạnh Phúc
A4: DEBIT NOTE
A6: Căn cứ vào tình hình thực tế thực hiện,
A7: Chúng tôi gồm:
A8: BÊN MUA: CÔNG TY TNHH CANON VIỆT NAM - CHI NHÁNH TIÊN SƠN
A9: Địa chỉ: Số 12, đường TS10, Khu công nghiệp Tiên Sơn, Xã Đại Đồng, Tỉnh Bắc Ninh, Việt Nam
A10: MST: 0101125340002
A11: Đại diện: | D11: Chức vụ:
A13: BÊN BÁN: CÔNG TY CỔ PHẦN MBF
A14: Địa chỉ: Số 58 Xóm Giếng, Thôn Cổ Điển A, Xã Thanh Trì, Thành phố Hà Nội, Việt Nam
A15: MST: 0105040296
A16: Đại diện: | D16: Chức vụ:
A17: Cùng đối chiếu như sau:
C18: Debit No.: | D18: MBF-CTS11022026-3
C19: Date | D19: ='COVER DN XUẤT'!D19 -> 23/02/2026
A22: DESCRIPTION | E22: AMOUNT (VND) | F22: REMARK
A23: 1 | B23: Infrastructure expense | E23: ='CSHT XUẤT'!H89 -> 26750000
A24: 2 | B24: Lift on | E24: ='CSHT XUẤT'!M89 -> 51446000
A25: 3 | B25: Lift off | E25: ='CSHT XUẤT'!S89 -> 61472800
A26: 4 | B26: Other fees | E26: ='CSHT XUẤT'!Y89 -> 20000
A35: SUB TOTAL | E35: =E23+E24+E25+E26 -> 139688800
A36: VAT 0%
A37: TOTAL DEBIT | E37: =SUM(E35:E36) -> 139688800
D40: ='COVER DN XUẤT'!D41:H41 -> Ngày 23 tháng 02 năm 2026
D42: ĐẠI DIỆN BÊN BÁN

Sheet CSHT XUẤT
A1: CỘNG HÒA XÃ HỘI CHỦ NGHĨA VIỆT NAM | AI1: 0
A2: Độc lập - Tự do - Hạnh Phúc
A4: BACK TO BACK CHARGE
A6: Căn cứ vào tình hình thực tế thực hiện,
A7: Chúng tôi gồm:
A8: BÊN MUA: CÔNG TY TNHH CANON VIỆT NAM - CHI NHÁNH TIÊN SƠN
A9: Địa chỉ: Số 12, đường TS10, Khu công nghiệp Tiên Sơn, Xã Đại Đồng, Tỉnh Bắc Ninh, Việt Nam
A10: MST: 0101125340002
A11: Đại diện: | D11: Chức vụ:
A13: BÊN BÁN: CÔNG TY CỔ PHẦN MBF
A14: Địa chỉ: Số 58 Xóm Giếng, Thôn Cổ Điển A, Xã Thanh Trì, Thành phố Hà Nội, Việt Nam
A15: MST: 0105040296
A16: Đại diện: | D16: Chức vụ:
A17: Cùng đối chiếu như sau:
O19: Date | Q19: ='COVER BTB XUẤT'!C18 -> Debit No.: | R19: ='COVER BTB XUẤT'!D18 -> MBF-CTS11022026-3
Q20: ='COVER BTB XUẤT'!C19 -> Date | R20: ='COVER BTB XUẤT'!D19 -> 23/02/2026
A21: STT | B21: Ngày đóng hàng | C21: BL/ BKG | D21: Tờ khai | E21: Loại Conts | F21: CVN Invoice no | G21: Số Conts | H21: Chi hộ CSHT | I21: Invoice no | J21: Invoice date | K21: Net amount | L21: VAT | M21: Lift on | N21: Invoice no | O21: Invoice date | P21: Tên nhà cung cấp | Q21: Net amount | R21: VAT | S21: Lift off | T21: Invoice no | U21: Invoice date | V21: Tên nhà cung cấp | W21: Net amount | X21: VAT | Y21: Other fees | Z21: Invoice no | AA21: Invoice date | AB21: Tên nhà cung cấp | AC21: Total | AD21: Note | AM21: 0
A22: =ROW()-21 -> 1 | B22: 46038 | C22: 237500707611 | D22: =VLOOKUP(G22,[1]Sheet1!$I$1:$Q$180000,9,0) -> 308158278210 | E22: 40HC | F22: VS-26/50066 | G22: EMCU8313605 | H22: 500000 | I22: =$AI$1&AI22 -> 0614521 | J22: =VLOOKUP(D22,'web CSHT'!$J$4:$Q$110000,6,0) -> 46039 | K22: =M22/1.08 -> 1450000 | L22: =M22-K22 -> 116000 | M22: 1566000 | N22: 3537 | O22: 46038 | P22: CÔNG TY CỔ PHẦN VSC GREEN LOGISTICS | Q22: =S22/1.08 -> 1500000 | R22: =S22-Q22 -> 120000 | S22: 1620000 | T22: 3538 | U22: 16/01/2026 | V22: CÔNG TY CỔ PHẦN VSC GREEN LOGISTICS | AC22: =H22+M22+S22+Y22 -> 3686000 | AE22: Lấy HPH - TS EX - Hạ HPH Disconnect | AF22: GIC | AG22: GIC | AI22: =VLOOKUP(D22,'web CSHT'!$J$4:$Q$170000,5,0) -> 614521 | AJ22: =VLOOKUP(D22,'web CSHT'!$J$4:$Q$170000,8,0) -> 500 | AK22: EMCU8313605 | AL22: =EXACT(G22,AK22) -> TRUE
A23: =ROW()-21 -> 2 | B23: 46038 | C23: HPH26A00675 | D23: =VLOOKUP(G23,[1]Sheet1!$I$1:$Q$180000,9,0) -> 308158323820 | E23: 40HC | F23: VF-26/50009 | G23: NSSU7171637 | H23: 500000 | I23: =$AI$1&AI23 -> 0615587 | J23: =VLOOKUP(D23,'web CSHT'!$J$4:$Q$110000,6,0) -> 46041 | K23: =M23/1.08 -> 1450000 | L23: =M23-K23 -> 116000 | M23: 1566000 | N23: 3608 | O23: 16/01/2026 | P23: CÔNG TY CỔ PHẦN VSC GREEN LOGISTICS | Q23: =S23/1.08 -> 1640000 | R23: =S23-Q23 -> 131200 | S23: 1771200 | T23: 7033 | U23: 17/01/2026 | V23: CÔNG TY CỔ PHẦN CẢNG XANH VIP | AC23: =H23+M23+S23+Y23 -> 3837200 | AE23: Lấy HPH - TS EX - Hạ HPH Connect | AF23: GIC | AG23: VIP GREEN PORT | AI23: =VLOOKUP(D23,'web CSHT'!$J$4:$Q$170000,5,0) -> 615587 | AJ23: =VLOOKUP(D23,'web CSHT'!$J$4:$Q$170000,8,0) -> 500 | AK23: NSSU7171637 | AL23: =EXACT(G23,AK23) -> TRUE
A24: =ROW()-21 -> 3 | B24: 46038 | C24: 237500707611 | D24: =VLOOKUP(G24,[1]Sheet1!$I$1:$Q$180000,9,0) -> 308158430550 | E24: 40HC | F24: VS-26/50065 | G24: BMOU6012145 | H24: 500000 | I24: =$AI$1&AI24 -> 0614527 | J24: =VLOOKUP(D24,'web CSHT'!$J$4:$Q$110000,6,0) -> 46039 | K24: =M24/1.08 -> 1450000 | L24: =M24-K24 -> 116000 | M24: 1566000 | N24: 3572 | O24: 16/01/2026 | P24: CÔNG TY CỔ PHẦN VSC GREEN LOGISTICS | Q24: =S24/1.08 -> 1500000 | R24: =S24-Q24 -> 120000 | S24: 1620000 | T24: 3840 | U24: 17/01/2026 | V24: CÔNG TY CỔ PHẦN VSC GREEN LOGISTICS | AC24: =H24+M24+S24+Y24 -> 3686000 | AE24: Lấy HPH - TS EX - Hạ HPH Disconnect | AF24: GIC | AG24: GIC | AI24: =VLOOKUP(D24,'web CSHT'!$J$4:$Q$170000,5,0) -> 614527 | AJ24: =VLOOKUP(D24,'web CSHT'!$J$4:$Q$170000,8,0) -> 500 | AK24: BMOU6012145 | AL24: =EXACT(G24,AK24) -> TRUE
A25: =ROW()-21 -> 4 | B25: 46038 | C25: 237500707611 | D25: =VLOOKUP(G25,[1]Sheet1!$I$1:$Q$180000,9,0) -> 308158509650 | E25: 40HC | F25: VS-26/50067 | G25: EGSU9553960 | H25: 500000 | I25: =$AI$1&AI25 -> 0614522 | J25: =VLOOKUP(D25,'web CSHT'!$J$4:$Q$110000,6,0) -> 46039 | K25: =M25/1.08 -> 1450000 | L25: =M25-K25 -> 116000 | M25: 1566000 | N25: 3716 | O25: 16/01/2026 | P25: CÔNG TY CỔ PHẦN VSC GREEN LOGISTICS | Q25: =S25/1.08 -> 1500000 | R25: =S25-Q25 -> 120000 | S25: 1620000 | T25: 3860 | U25: 17/01/2026 | V25: CÔNG TY CỔ PHẦN VSC GREEN LOGISTICS | AC25: =H25+M25+S25+Y25 -> 3686000 | AE25: Lấy HPH - TS EX - Hạ HPH Connect | AF25: GIC | AG25: GIC | AI25: =VLOOKUP(D25,'web CSHT'!$J$4:$Q$170000,5,0) -> 614522 | AJ25: =VLOOKUP(D25,'web CSHT'!$J$4:$Q$170000,8,0) -> 500 | AK25: EGSU9553960 | AL25: =EXACT(G25,AK25) -> TRUE
A26: =ROW()-21 -> 5 | B26: 46038 | C26: SGN2987352 | D26: =VLOOKUP(G26,[1]Sheet1!$I$1:$Q$180000,9,0) -> 308158360000 | E26: 40HC | F26: VH-26/50087 | G26: TRHU5424799 | H26: 500000 | I26: =$AI$1&AI26 -> 0615579 | J26: =VLOOKUP(D26,'web CSHT'!$J$4:$Q$110000,6,0) -> 46041 | P26: X | V26: X | AC26: =H26+M26+S26+Y26 -> 500000 | AE26: Lấy Hưng Yên - RU TS EX - Hạ HPH | AF26: RU HY | AG26: TÂN VŨ | AI26: =VLOOKUP(D26,'web CSHT'!$J$4:$Q$170000,5,0) -> 615579 | AJ26: =VLOOKUP(D26,'web CSHT'!$J$4:$Q$170000,8,0) -> 500 | AK26: TRHU5424799 | AL26: =EXACT(G26,AK26) -> TRUE
A27: =ROW()-21 -> 6 | B27: 46038 | C27: SGN2991014 | D27: =VLOOKUP(G27,[1]Sheet1!$I$1:$Q$180000,9,0) -> 308158391130 | E27: 40HC | F27: VH-26/50089 | G27: TCNU7535165 | H27: 500000 | I27: =$AI$1&AI27 -> 0615554 | J27: =VLOOKUP(D27,'web CSHT'!$J$4:$Q$110000,6,0) -> 46041 | P27: X | V27: X | AC27: =H27+M27+S27+Y27 -> 500000 | AE27: Lấy Hưng Yên - RU TS EX - Hạ HPH | AF27: RU HY | AG27: TÂN VŨ | AI27: =VLOOKUP(D27,'web CSHT'!$J$4:$Q$170000,5,0) -> 615554 | AJ27: =VLOOKUP(D27,'web CSHT'!$J$4:$Q$170000,8,0) -> 500 | AK27: TCNU7535165 | AL27: =EXACT(G27,AK27) -> TRUE
A28: =ROW()-21 -> 7 | B28: 46041 | C28: BHAIC26000188 | D28: =VLOOKUP(G28,[1]Sheet1!$I$1:$Q$180000,9,0) -> 308163768160 | E28: 40HC | F28: VS-26/50079 | G28: REGU5201120 | H28: 500000 | I28: =$AI$1&AI28 -> 0617703 | J28: =VLOOKUP(D28,'web CSHT'!$J$4:$Q$110000,6,0) -> 46042 | K28: =M28/1.08 -> 1500000 | L28: =M28-K28 -> 120000 | M28: 1620000 | N28: 710 | O28: 18/01/2026 | P28: CÔNG TY CỔ PHẦN ICD NAM HẢI | Q28: =S28/1.08 -> 1640000 | R28: =S28-Q28 -> 131200 | S28: 1771200 | T28: 741 | U28: 19/01/2026 | V28: CÔNG TY CỔ PHẦN ICD NAM HẢI | AC28: =H28+M28+S28+Y28 -> 3891200 | AE28: Lấy HPH - TS EX - Hạ HPH Connect | AF28: NAM HẢI ICD | AG28: NAM HẢI ICD | AI28: =VLOOKUP(D28,'web CSHT'!$J$4:$Q$170000,5,0) -> 617703 | AJ28: =VLOOKUP(D28,'web CSHT'!$J$4:$Q$170000,8,0) -> 500 | AK28: REGU5201120 | AL28: =EXACT(G28,AK28) -> TRUE
A29: =ROW()-21 -> 8 | B29: 46041 | C29: 6438798511 | D29: =VLOOKUP(G29,[1]Sheet1!$I$1:$Q$180000,9,0) -> 308163870250 | E29: 40HC | F29: VS-26/50074 | G29: TIIU5347234 | H29: 500000 | I29: =$AI$1&AI29 -> 0617710 | J29: =VLOOKUP(D29,'web CSHT'!$J$4:$Q$110000,6,0) -> 46042 | P29: X | V29: X | AC29: =H29+M29+S29+Y29 -> 500000 | AE29: Lấy HPH - TS IM - RU TS EX - Hạ HPH | AF29: RU CTS | AG29: TÂN VŨ | AI29: =VLOOKUP(D29,'web CSHT'!$J$4:$Q$170000,5,0) -> 617710 | AJ29: =VLOOKUP(D29,'web CSHT'!$J$4:$Q$170000,8,0) -> 500 | AK29: TIIU5347234 | AL29: =EXACT(G29,AK29) -> TRUE
A30: =ROW()-21 -> 9 | B30: 46042 | C30: 6438798511 | D30: =VLOOKUP(G30,[1]Sheet1!$I$1:$Q$180000,9,0) -> 308169652730 | E30: 40HC | F30: VS-26/50089 | G30: CSNU8639981 | H30: 500000 | I30: =$AI$1&AI30 -> 0622642 | J30: =VLOOKUP(D30,'web CSHT'!$J$4:$Q$110000,6,0) -> 46045 | P30: X | V30: X | AC30: =H30+M30+S30+Y30 -> 500000 | AE30: Lấy Hưng Yên - RU TS EX - Hạ HPH | AF30: RU HY | AG30: TÂN VŨ | AI30: =VLOOKUP(D30,'web CSHT'!$J$4:$Q$170000,5,0) -> 622642 | AJ30: =VLOOKUP(D30,'web CSHT'!$J$4:$Q$170000,8,0) -> 500 | AK30: CSNU8639981 | AL30: =EXACT(G30,AK30) -> TRUE
A31: =ROW()-21 -> 10 | B31: 46043 | C31: 237600063367 | D31: 308173905600 | E31: 20DC | F31: VH-26/50108 | G31: EITU3162502 | H31: 250000 | I31: =$AI$1&AI31 -> 0634457 | J31: =VLOOKUP(D31,'web CSHT'!$J$4:$Q$110000,6,0) -> 46052 | K31: =M31/1.08 -> 1000000 | L31: =M31-K31 -> 80000 | M31: 1080000 | N31: 8036 | O31: 46042 | P31: CÔNG TY CỔ PHẦN THT E-LOGISTICS | Q31: =S31/1.08 -> 1150000 | R31: =S31-Q31 -> 92000 | S31: 1242000 | T31: 4755 | U31: 46043 | V31: CÔNG TY CỔ PHẦN VSC GREEN LOGISTICS | W31: 18519 | X31: =Y31-W31 -> 1481 | Y31: 20000 | Z31: 25395 | AA31: 46042 | AB31: CÔNG TY CỔ PHẦN ỨNG DỤNG CÔNG NGHỆ LOGISTICS | AC31: =H31+M31+S31+Y31 -> 2592000 | AE31: Lấy HPH - TS EX - Hạ HPH Disconnect | AF31: CHÂN THẬT | AG31: GIC | AI31: =VLOOKUP(D31,'web CSHT'!$J$4:$Q$170000,5,0) -> 634457 | AJ31: =VLOOKUP(D31,'web CSHT'!$J$4:$Q$170000,8,0) -> 250 | AK31: EITU3162502 | AL31: =EXACT(G31,AK31) -> TRUE
A32: =ROW()-21 -> 11 | B32: 46045 | C32: 237500733123 | D32: =VLOOKUP(G32,[1]Sheet1!$I$1:$Q$180000,9,0) -> 308182232540 | E32: 40HC | F32: VH-26/50120 | G32: EGSU6484249 | H32: 500000 | I32: =$AI$1&AI32 -> 0629727 | J32: =VLOOKUP(D32,'web CSHT'!$J$4:$Q$110000,6,0) -> 46050 | K32: =M32/1.08 -> 1450000 | L32: =M32-K32 -> 116000 | M32: 1566000 | N32: 5223 | O32: 23/01/2026 | P32: CÔNG TY CỔ PHẦN VSC GREEN LOGISTICS | Q32: =S32/1.08 -> 1500000 | R32: =S32-Q32 -> 120000 | S32: 1620000 | T32: 6102 | U32: 28/01/2026 | V32: CÔNG TY CỔ PHẦN VSC GREEN LOGISTICS | AC32: =H32+M32+S32+Y32 -> 3686000 | AE32: Lấy HPH - TS EX - Hạ HPH Disconnect | AF32: GIC | AG32: GIC | AI32: =VLOOKUP(D32,'web CSHT'!$J$4:$Q$170000,5,0) -> 629727 | AJ32: =VLOOKUP(D32,'web CSHT'!$J$4:$Q$170000,8,0) -> 500 | AK32: EGSU6484249 | AL32: =EXACT(G32,AK32) -> TRUE
A33: =ROW()-21 -> 12 | B33: 46045 | C33: 237500736122 | D33: =VLOOKUP(G33,[1]Sheet1!$I$1:$Q$180000,9,0) -> 308181125140 | E33: 40HC | F33: VS-26/50113 | G33: TGBU6583045 | H33: 500000 | I33: =$AI$1&AI33 -> 0626254 | J33: =VLOOKUP(D33,'web CSHT'!$J$4:$Q$110000,6,0) -> 46048 | K33: =M33/1.08 -> 1500000 | L33: =M33-K33 -> 120000 | M33: 1620000 | N33: 22815 | O33: 26/01/2026 | P33: CÔNG TY CỔ PHẦN GREATING FORTUNE CONTAINER VIỆT NAM | Q33: =S33/1.08 -> 1500000 | R33: =S33-Q33 -> 120000 | S33: 1620000 | T33: 5383 | U33: 24/01/2026 | V33: CÔNG TY CỔ PHẦN VSC GREEN LOGISTICS | AC33: =H33+M33+S33+Y33 -> 3740000 | AE33: Lấy HPH - TS EX - Hạ HPH Connect | AF33: GFORTUNE | AG33: GIC | AI33: =VLOOKUP(D33,'web CSHT'!$J$4:$Q$170000,5,0) -> 626254 | AJ33: =VLOOKUP(D33,'web CSHT'!$J$4:$Q$170000,8,0) -> 500 | AK33: TGBU6583045 | AL33: =EXACT(G33,AK33) -> TRUE
A34: =ROW()-21 -> 13 | B34: 46045 | C34: 237500737447 | D34: =VLOOKUP(G34,[1]Sheet1!$I$1:$Q$180000,9,0) -> 308182479050 | E34: 40HC | F34: VS-26/50107 | G34: EGHU9330270 | H34: 500000 | I34: =$AI$1&AI34 -> 0626251 | J34: =VLOOKUP(D34,'web CSHT'!$J$4:$Q$110000,6,0) -> 46048 | K34: =M34/1.08 -> 1500000 | L34: =M34-K34 -> 120000 | M34: 1620000 | N34: 22837 | O34: 26/01/2026 | P34: CÔNG TY CỔ PHẦN GREATING FORTUNE CONTAINER VIỆT NAM | Q34: =S34/1.08 -> 1500000 | R34: =S34-Q34 -> 120000 | S34: 1620000 | T34: 5354 | U34: 24/01/2026 | V34: CÔNG TY CỔ PHẦN VSC GREEN LOGISTICS | AC34: =H34+M34+S34+Y34 -> 3740000 | AE34: Lấy HPH - TS EX - Hạ HPH Disconnect | AF34: GFORTUNE | AG34: GIC | AI34: =VLOOKUP(D34,'web CSHT'!$J$4:$Q$170000,5,0) -> 626251 | AJ34: =VLOOKUP(D34,'web CSHT'!$J$4:$Q$170000,8,0) -> 500 | AK34: EGHU9330270 | AL34: =EXACT(G34,AK34) -> TRUE
A35: =ROW()-21 -> 14 | B35: 46046 | C35: 237500737447 | D35: =VLOOKUP(G35,[1]Sheet1!$I$1:$Q$180000,9,0) -> 308184601230 | E35: 40HC | F35: VS-26/50115 | G35: TIIU5457859 | H35: 500000 | I35: =$AI$1&AI35 -> 0626274 | J35: =VLOOKUP(D35,'web CSHT'!$J$4:$Q$110000,6,0) -> 46048 | K35: =M35/1.08 -> 1500000 | L35: =M35-K35 -> 120000 | M35: 1620000 | N35: 22906 | O35: 26/01/2026 | P35: CÔNG TY CỔ PHẦN GREATING FORTUNE CONTAINER VIỆT NAM | Q35: =S35/1.08 -> 1500000 | R35: =S35-Q35 -> 120000 | S35: 1620000 | T35: 5605 | U35: 46048 | V35: CÔNG TY CỔ PHẦN VSC GREEN LOGISTICS | AC35: =H35+M35+S35+Y35 -> 3740000 | AE35: Lấy HPH - TS EX - Hạ HPH Disconnect | AF35: GFORTUNE | AG35: GIC | AI35: =VLOOKUP(D35,'web CSHT'!$J$4:$Q$170000,5,0) -> 626274 | AJ35: =VLOOKUP(D35,'web CSHT'!$J$4:$Q$170000,8,0) -> 500 | AK35: TIIU5457859 | AL35: =EXACT(G35,AK35) -> TRUE
A36: =ROW()-21 -> 15 | B36: 46046 | C36: 237500736122 | D36: =VLOOKUP(G36,[1]Sheet1!$I$1:$Q$180000,9,0) -> 308184642050 | E36: 40HC | F36: VS-26/50112 | G36: FFAU1594240 | H36: 500000 | I36: =$AI$1&AI36 -> 0626268 | J36: =VLOOKUP(D36,'web CSHT'!$J$4:$Q$110000,6,0) -> 46048 | K36: =M36/1.08 -> 1500000 | L36: =M36-K36 -> 120000 | M36: 1620000 | N36: 22900 | O36: 26/01/2026 | P36: CÔNG TY CỔ PHẦN GREATING FORTUNE CONTAINER VIỆT NAM | Q36: =S36/1.08 -> 1500000 | R36: =S36-Q36 -> 120000 | S36: 1620000 | T36: 5444 | U36: 24/01/2026 | V36: CÔNG TY CỔ PHẦN VSC GREEN LOGISTICS | AC36: =H36+M36+S36+Y36 -> 3740000 | AE36: Lấy HPH - TS EX - Hạ HPH Disconnect | AF36: GFORTUNE | AG36: GIC | AI36: =VLOOKUP(D36,'web CSHT'!$J$4:$Q$170000,5,0) -> 626268 | AJ36: =VLOOKUP(D36,'web CSHT'!$J$4:$Q$170000,8,0) -> 500 | AK36: FFAU1594240 | AL36: =EXACT(G36,AK36) -> TRUE
A37: =ROW()-21 -> 16 | B37: 46046 | C37: 237500733123 | D37: =VLOOKUP(G37,[1]Sheet1!$I$1:$Q$180000,9,0) -> 308184728520 | E37: 40HC | F37: VH-26/50128 | G37: EGSU6484172 | H37: 500000 | I37: =$AI$1&AI37 -> 0626275 | J37: =VLOOKUP(D37,'web CSHT'!$J$4:$Q$110000,6,0) -> 46048 | K37: =M37/1.08 -> 1450000 | L37: =M37-K37 -> 116000 | M37: 1566000 | N37: 5425 | O37: 24/01/2026 | P37: CÔNG TY CỔ PHẦN VSC GREEN LOGISTICS | Q37: =S37/1.08 -> 1500000 | R37: =S37-Q37 -> 120000 | S37: 1620000 | T37: 5492 | U37: 25/01/2026 | V37: CÔNG TY CỔ PHẦN VSC GREEN LOGISTICS | AC37: =H37+M37+S37+Y37 -> 3686000 | AE37: Lấy HPH - TS EX - Hạ HPH Connect | AF37: GIC | AG37: GIC | AI37: =VLOOKUP(D37,'web CSHT'!$J$4:$Q$170000,5,0) -> 626275 | AJ37: =VLOOKUP(D37,'web CSHT'!$J$4:$Q$170000,8,0) -> 500 | AK37: EGSU6484172 | AL37: =EXACT(G37,AK37) -> TRUE
A38: =ROW()-21 -> 17 | B38: 46046 | C38: 237500733123 | D38: =VLOOKUP(G38,[1]Sheet1!$I$1:$Q$180000,9,0) -> 308184527510 | E38: 40HC | F38: VH-26/50129 | G38: EGSU6489718 | H38: 500000 | I38: =$AI$1&AI38 -> 0626264 | J38: =VLOOKUP(D38,'web CSHT'!$J$4:$Q$110000,6,0) -> 46048 | K38: =M38/1.08 -> 1450000 | L38: =M38-K38 -> 116000 | M38: 1566000 | N38: 5401 | O38: 24/01/2026 | P38: CÔNG TY CỔ PHẦN VSC GREEN LOGISTICS | Q38: =S38/1.08 -> 1500000 | R38: =S38-Q38 -> 120000 | S38: 1620000 | T38: 5631 | U38: 26/01/2026 | V38: CÔNG TY CỔ PHẦN VSC GREEN LOGISTICS | AC38: =H38+M38+S38+Y38 -> 3686000 | AE38: Lấy HPH - TS EX - Hạ HPH Connect | AF38: GIC | AG38: GIC | AI38: =VLOOKUP(D38,'web CSHT'!$J$4:$Q$170000,5,0) -> 626264 | AJ38: =VLOOKUP(D38,'web CSHT'!$J$4:$Q$170000,8,0) -> 500 | AK38: EGSU6489718 | AL38: =EXACT(G38,AK38) -> TRUE
A39: =ROW()-21 -> 18 | B39: 46048 | C39: 237500736122 | D39: =VLOOKUP(G39,[1]Sheet1!$I$1:$Q$180000,9,0) -> 308188076360 | E39: 40HC | F39: VH-26/50138 | G39: EGHU9777247 | H39: 500000 | I39: =$AI$1&AI39 -> 0629721 | J39: =VLOOKUP(D39,'web CSHT'!$J$4:$Q$110000,6,0) -> 46050 | K39: =M39/1.08 -> 1500000 | L39: =M39-K39 -> 120000 | M39: 1620000 | N39: 24372 | O39: 27/01/2026 | P39: CÔNG TY CỔ PHẦN GREATING FORTUNE CONTAINER VIỆT NAM | Q39: =S39/1.08 -> 1500000 | R39: =S39-Q39 -> 120000 | S39: 1620000 | T39: 5921 | U39: 27/01/2026 | V39: CÔNG TY CỔ PHẦN VSC GREEN LOGISTICS | AC39: =H39+M39+S39+Y39 -> 3740000 | AE39: Lấy HPH - TS EX - Hạ HPH Disconnect | AF39: GFORTUNE | AG39: GIC | AI39: =VLOOKUP(D39,'web CSHT'!$J$4:$Q$170000,5,0) -> 629721 | AJ39: =VLOOKUP(D39,'web CSHT'!$J$4:$Q$170000,8,0) -> 500 | AK39: EGHU9777247 | AL39: =EXACT(G39,AK39) -> TRUE
A40: =ROW()-21 -> 19 | B40: 46048 | C40: HANA57597700 | D40: =VLOOKUP(G40,[1]Sheet1!$I$1:$Q$180000,9,0) -> 308188091320 | E40: 40HC | F40: VS-26/50105 | G40: HMMU7026820 | H40: 500000 | I40: =$AI$1&AI40 -> 0632025 | J40: =VLOOKUP(D40,'web CSHT'!$J$4:$Q$110000,6,0) -> 46051 | K40: =M40/1.08 -> 1500000 | L40: =M40-K40 -> 120000 | M40: 1620000 | N40: 4627 | O40: 26/01/2026 | P40: CÔNG TY CỔ PHẦN TÂN CẢNG 128 - HẢI PHÒNG | Q40: 1435185 | R40: =S40-Q40 -> 114815 | S40: 1550000 | T40: 4750 | U40: 28/01/2026 | V40: CÔNG TY TNHH HÀ HƯNG HẢI | AC40: =H40+M40+S40+Y40 -> 3670000 | AE40: Lấy HPH - TS EX - Hạ HPH Disconnect | AF40: TÂN CẢNG 128 | AG40: HÀ HƯNG HẢI | AI40: =VLOOKUP(D40,'web CSHT'!$J$4:$Q$170000,5,0) -> 632025 | AJ40: =VLOOKUP(D40,'web CSHT'!$J$4:$Q$170000,8,0) -> 500 | AK40: HMMU7026820 | AL40: =EXACT(G40,AK40) -> TRUE
A41: =ROW()-21 -> 20 | B41: 46049 | C41: 237500733123 | D41: =VLOOKUP(G41,[1]Sheet1!$I$1:$Q$180000,9,0) -> 308193111610 | E41: 40HC | F41: VH-26/50144 | G41: GCXU6443400 | H41: 500000 | I41: =$AI$1&AI41 -> 0629728 | J41: =VLOOKUP(D41,'web CSHT'!$J$4:$Q$110000,6,0) -> 46050 | K41: =M41/1.08 -> 1450000 | L41: =M41-K41 -> 116000 | M41: 1566000 | N41: 6036 | O41: 27/01/2026 | P41: CÔNG TY CỔ PHẦN VSC GREEN LOGISTICS | Q41: =S41/1.08 -> 1500000 | R41: =S41-Q41 -> 120000 | S41: 1620000 | T41: 6232 | U41: 28/01/2026 | V41: CÔNG TY CỔ PHẦN VSC GREEN LOGISTICS | AC41: =H41+M41+S41+Y41 -> 3686000 | AE41: Lấy HPH - TS EX - Hạ HPH Disconnect | AF41: GIC | AG41: GIC | AI41: =VLOOKUP(D41,'web CSHT'!$J$4:$Q$170000,5,0) -> 629728 | AJ41: =VLOOKUP(D41,'web CSHT'!$J$4:$Q$170000,8,0) -> 500 | AK41: GCXU6443400 | AL41: =EXACT(G41,AK41) -> TRUE
A42: =ROW()-21 -> 21 | B42: 46051 | C42: 237600097369 | D42: =VLOOKUP(G42,[1]Sheet1!$I$1:$Q$180000,9,0) -> 308202099500 | E42: 40HC | F42: VH-26/50156 | G42: EGSU1600794 | H42: 500000 | I42: =$AI$1&AI42 -> 0634467 | J42: =VLOOKUP(D42,'web CSHT'!$J$4:$Q$110000,6,0) -> 46052 | K42: 1388889 | L42: =M42-K42 -> 111111 | M42: 1500000 | N42: 20853 | O42: 02/02/2026 | P42: CÔNG TY CỔ PHẦN ĐẦU TƯ SAO Á D.C | Q42: =S42/1.08 -> 1500000 | R42: =S42-Q42 -> 120000 | S42: 1620000 | T42: 6766 | U42: 30/01/2026 | V42: CÔNG TY CỔ PHẦN VSC GREEN LOGISTICS | AC42: =H42+M42+S42+Y42 -> 3620000 | AE42: Lấy HPH - TS EX - Hạ HPH Connect | AF42: SAO Á | AG42: GIC | AI42: =VLOOKUP(D42,'web CSHT'!$J$4:$Q$170000,5,0) -> 634467 | AJ42: =VLOOKUP(D42,'web CSHT'!$J$4:$Q$170000,8,0) -> 500 | AK42: EGSU1600794 | AL42: =EXACT(G42,AK42) -> TRUE
A43: =ROW()-21 -> 22 | B43: 46051 | C43: 237600056956 | D43: =VLOOKUP(G43,[1]Sheet1!$I$1:$Q$180000,9,0) -> 308202123520 | E43: 40HC | F43: VS-26/50138 | G43: TLLU7977255 | H43: 500000 | I43: =$AI$1&AI43 -> 0634473 | J43: =VLOOKUP(D43,'web CSHT'!$J$4:$Q$110000,6,0) -> 46052 | K43: =M43/1.08 -> 1500000 | L43: =M43-K43 -> 120000 | M43: 1620000 | N43: 29387 | O43: 31/01/2026 | P43: CÔNG TY CỔ PHẦN GREATING FORTUNE CONTAINER VIỆT NAM | Q43: =S43/1.08 -> 1500000 | R43: =S43-Q43 -> 120000 | S43: 1620000 | T43: 6813 | U43: 30/01/2026 | V43: CÔNG TY CỔ PHẦN VSC GREEN LOGISTICS | AC43: =H43+M43+S43+Y43 -> 3740000 | AE43: Lấy HPH - TS EX - Hạ HPH Connect | AF43: GFORTUNE | AG43: GIC | AI43: =VLOOKUP(D43,'web CSHT'!$J$4:$Q$170000,5,0) -> 634473 | AJ43: =VLOOKUP(D43,'web CSHT'!$J$4:$Q$170000,8,0) -> 500 | AK43: TLLU7977255 | AL43: =EXACT(G43,AK43) -> TRUE
A44: =ROW()-21 -> 23 | B44: 46051 | C44: SGN3036238 | D44: 308202052820 | E44: 40HC | F44: VH-26/50157 | G44: CMAU7489161 | H44: 500000 | I44: =$AI$1&AI44 -> 0634466 | J44: =VLOOKUP(D44,'web CSHT'!$J$4:$Q$110000,6,0) -> 46052 | P44: X | V44: X | AC44: =H44+M44+S44+Y44 -> 500000 | AE44: Lấy Hưng Yên - RU TS EX - Hạ HPH | AF44: RU HY | AG44: TÂN VŨ | AI44: =VLOOKUP(D44,'web CSHT'!$J$4:$Q$170000,5,0) -> 634466 | AJ44: =VLOOKUP(D44,'web CSHT'!$J$4:$Q$170000,8,0) -> 500 | AK44: CMAU7489161 | AL44: =EXACT(G44,AK44) -> TRUE
...

Sheet CSHT XUẤT (2)
A1: CỘNG HÒA XÃ HỘI CHỦ NGHĨA VIỆT NAM
A2: Độc lập - Tự do - Hạnh Phúc
A4: BACK TO BACK CHARGE
A6: Căn cứ vào tình hình thực tế thực hiện,
A7: Chúng tôi gồm:
A8: BÊN MUA: CÔNG TY TNHH CANON VIỆT NAM - CHI NHÁNH TIÊN SƠN
A9: Địa chỉ: Số 12, đường TS10, Khu công nghiệp Tiên Sơn, Xã Đại Đồng, Tỉnh Bắc Ninh, Việt Nam | AE9: đã check LOLO < CSHT
A10: MST: 0101125340002 | AE10: LOLO thiếu 1 cái
A11: Đại diện: | D11: Chức vụ:
A13: BÊN BÁN: CÔNG TY CỔ PHẦN MBF
A14: Địa chỉ: Số 58 Xóm Giếng, Thôn Cổ Điển A, Xã Thanh Trì, Thành phố Hà Nội, Việt Nam
A15: MST: 0105040296
A16: Đại diện: | D16: Chức vụ:
A17: Cùng đối chiếu như sau:
O19: Date | Q19: ='COVER BTB XUẤT'!C18 -> Debit No.: | R19: ='COVER BTB XUẤT'!D18 -> MBF-CTS11022026-3
Q20: ='COVER BTB XUẤT'!C19 -> Date | R20: ='COVER BTB XUẤT'!D19 -> 23/02/2026
A21: STT | B21: Ngày đóng hàng | C21: BL/ BKG | D21: Tờ khai | E21: Loại Conts | F21: CVN Invoice no | G21: Số Conts | H21: Chi hộ CSHT | I21: Invoice no | J21: Invoice date | K21: Net amount | L21: VAT | M21: Lift on | N21: Invoice no | O21: Invoice date | P21: Tên nhà cung cấp | Q21: Net amount | R21: VAT | S21: Lift off | T21: Invoice no | U21: Invoice date | V21: Tên nhà cung cấp | W21: Net amount | X21: VAT | Y21: Other fees | Z21: Invoice no | AA21: Invoice date | AB21: Tên nhà cung cấp | AC21: Total | AD21: Note | AH21: HASU5183873 | AI21: truck + CSHT 500 | AM21: 0
A22: =ROW()-21 -> 1 | B22: 45930 | C22: COSU6430502490 | D22: 307814412900 | E22: 20DC | F22: VH-25/50559 | G22: BMOU1626095 | H22: 250000 | I22: 0468530 | J22: 45931 | K22: 925926 | L22: =M22-K22 -> 74074 | M22: 1000000 | N22: 110074 | O22: 30/09/2025 | P22: CÔNG TY CỔ PHẦN THT E-LOGISTICS | Q22: =S22/1.08 -> 1045000 | R22: =S22-Q22 -> 83600 | S22: 1128600 | T22: 203812 | U22: 30/09/2025 | V22: CÔNG TY TNHH CẢNG CONTAINER QUỐC TẾ TÂN CẢNG HẢI PHÒNG | W22: 18519 | X22: =Y22-W22 -> 1481 | Y22: 20000 | Z22: 326472 | AA22: 30/09/2025 | AB22: CÔNG TY CỔ PHẦN ỨNG DỤNG CÔNG NGHỆ LOGISTICS | AC22: =H22+M22+S22+Y22 -> 2398600 | AF22: Lấy HPH - TS EX - Hạ Lạch Huyện Disconnect | AG22: CHÂN THẬT | AH22: LẠCH HUYỆN | AL22: =VLOOKUP(D22,'web CSHT'!$J$4:$Q$18000,8,0) -> #N/A
A23: =ROW()-21 -> 2 | B23: 45930 | C23: 6426370150 | D23: 307814401810 | E23: 40HC | F23: VH-25/50557 | G23: CCLU7618857 | H23: 500000 | I23: 0470842 | J23: 45932 | Q23: =S23/1.08 -> 1490000 | R23: =S23-Q23 -> 119200 | S23: 1609200 | T23: 314072 | U23: 02/10/2025 | V23: CÔNG TY CỔ PHẦN CẢNG NAM ĐÌNH VŨ | AC23: =H23+M23+S23+Y23 -> 2109200 | AF23: Lấy HPH - TS IM - RU TS EX - Hạ HPH | AG23: RU CTS | AH23: NAM ĐÌNH VŨ | AL23: =VLOOKUP(D23,'web CSHT'!$J$4:$Q$18000,8,0) -> #N/A
A24: =ROW()-21 -> 3 | B24: 45930 | C24: 6426006020 | D24: 307815923940 | E24: 40HC | F24: VB-25/52406 | G24: OOLU9973630 | H24: 500000 | I24: 0471952 | J24: 45933 | Q24: =S24/1.08 -> 1490000 | R24: =S24-Q24 -> 119200 | S24: 1609200 | T24: 314109 | U24: 02/10/2025 | V24: CÔNG TY CỔ PHẦN CẢNG NAM ĐÌNH VŨ | AC24: =H24+M24+S24+Y24 -> 2109200 | AF24: Lấy HPH - TS IM - RU TS EX - Hạ HPH | AG24: RU CTS | AH24: NAM ĐÌNH VŨ | AL24: =VLOOKUP(D24,'web CSHT'!$J$4:$Q$18000,8,0) -> #N/A
A25: =ROW()-21 -> 4 | B25: 45931 | C25: HL-90526403 | D25: 307810809740 | E25: 40HC | F25: VS-25/51485 | G25: TCNU3272667 | H25: 500000 | I25: 0470834 | J25: 45932 | Q25: =S25/1.08 -> 1430000 | R25: =S25-Q25 -> 114400 | S25: 1544400 | T25: 136730 | U25: 01/10/2025 | V25: CÔNG TYCỔ PHẦN CẢNG CONTAINER QUỐC TẾ HATECO HẢI PHÒNG | AC25: =H25+M25+S25+Y25 -> 2044400 | AF25: TP - TS - TP + Hạ Lạch Huyện | AG25: TRI PHƯƠNG | AH25: HATECO | AL25: =VLOOKUP(D25,'web CSHT'!$J$4:$Q$18000,8,0) -> #N/A
A26: =ROW()-21 -> 5 | B26: 45933 | C26: SGN2820714 | D26: 307826690750 | E26: 40HC | F26: VB-25/52429 | G26: ECMU7001177 | H26: 500000 | I26: 0473169 | J26: 45934 | Q26: =S26/1.08 -> 1430000 | R26: =S26-Q26 -> 114400 | S26: 1544400 | T26: 147162 | U26: 45952 | V26: CÔNG TYCỔ PHẦN CẢNG CONTAINER QUỐC TẾ HATECO HẢI PHÒNG | AC26: =H26+M26+S26+Y26 -> 2044400 | AE26: Sai MST vì X MBF | AF26: Lấy Hưng Yên - TS EX - Hạ Lạch Huyện | AG26: RU HY | AH26: HATECO | AL26: =VLOOKUP(D26,'web CSHT'!$J$4:$Q$18000,8,0) -> #N/A
A27: =ROW()-21 -> 6 | B27: 45939 | C27: SGN2854099 | D27: 307842246740 | E27: 40HC | F27: VS-25/51517 | G27: BEAU5638649 | H27: 500000 | I27: 0479952 | J27: 45940 | V27: X | AC27: =H27+M27+S27+Y27 -> 500000 | AF27: Lấy Hưng Yên - TS EX - Hạ HPH | AG27: RU HY | AH27: TÂN VŨ | AL27: =VLOOKUP(D27,'web CSHT'!$J$4:$Q$18000,8,0) -> #N/A
A28: =ROW()-21 -> 7 | B28: 45943 | C28: MAEU258665687 | D28: 307853234200 | E28: 40HC | F28: VB-25/52492 | G28: FFAU4783150 | H28: 500000 | I28: 0485280 | J28: 15/10/2025 | Q28: =S28/1.08 -> 1430000 | R28: =S28-Q28 -> 114400 | S28: 1544400 | T28: 142069 | U28: 13/10/2025 | V28: CÔNG TYCỔ PHẦN CẢNG CONTAINER QUỐC TẾ HATECO HẢI PHÒNG | AC28: =H28+M28+S28+Y28 -> 2044400 | AF28: Lấy HPH - Trả nhập 2 điểm TL , TS - RU TS EX - Hạ Lạch Huyện | AG28: RU CTS | AH28: HATECO | AL28: =VLOOKUP(D28,'web CSHT'!$J$4:$Q$18000,8,0) -> #N/A
A29: =ROW()-21 -> 8 | B29: 45943 | C29: COSU6431337920 | D29: 307852473960 | E29: 40HC | F29: VH-25/50583 | G29: TGBU7691949 | H29: 500000 | I29: 0484126 | J29: 14/10/2025 | Q29: =S29/1.08 -> 1430000 | R29: =S29-Q29 -> 114400 | S29: 1544400 | T29: 213926 | U29: 13/10/2025 | V29: CÔNG TY TNHH CẢNG CONTAINER QUỐC TẾ TÂN CẢNG HẢI PHÒNG | AC29: =H29+M29+S29+Y29 -> 2044400 | AF29: Lấy HPH - TS IM - RU TS EX - Hạ Lạch Huyện | AG29: RU CTS | AH29: LẠCH HUYỆN | AL29: =VLOOKUP(D29,'web CSHT'!$J$4:$Q$18000,8,0) -> #N/A
A30: =ROW()-21 -> 9 | B30: 45943 | C30: COSU6431349580 | D30: 307852474810 | E30: 40HC | F30: VH-25/50584 | G30: OOCU7373769 | H30: 500000 | I30: 0484135 | J30: 14/10/2025 | Q30: =S30/1.08 -> 1430000 | R30: =S30-Q30 -> 114400 | S30: 1544400 | T30: 213930 | U30: 13/10/2025 | V30: CÔNG TY TNHH CẢNG CONTAINER QUỐC TẾ TÂN CẢNG HẢI PHÒNG | AC30: =H30+M30+S30+Y30 -> 2044400 | AF30: Lấy HPH - TS IM - RU TS EX - Hạ Lạch Huyện | AG30: RU CTS | AH30: LẠCH HUYỆN | AL30: =VLOOKUP(D30,'web CSHT'!$J$4:$Q$18000,8,0) -> #N/A
A31: =ROW()-21 -> 10 | B31: =VLOOKUP(G31,[3]T10!$Q$6:$S$1576,3,0) -> 45940 | C31: HL-78191313 | D31: 307831332230 | E31: 40HC | F31: VB-25/52445 | G31: FSCU8234806 | H31: 500000 | I31: 0479971 | J31: 45940 | Q31: =S31/1.08 -> 1430000 | R31: =S31-Q31 -> 114400 | S31: 1544400 | T31: 140822 | U31: 09/10/2025 | V31: CÔNG TYCỔ PHẦN CẢNG CONTAINER QUỐC TẾ HATECO HẢI PHÒNG | AC31: =H31+M31+S31+Y31 -> 2044400 | AF31: Lấy TP - TS EX - Hạ Lạch Huyện | AH31: HATECO | AL31: =VLOOKUP(D31,'web CSHT'!$J$4:$Q$18000,8,0) -> #N/A
A32: =ROW()-21 -> 11 | B32: =VLOOKUP(G32,[3]T10!$Q$6:$S$1576,3,0) -> 45941 | C32: HL-78191313 | D32: 307845870530 | E32: 40HC | F32: VB-25/52480 | G32: TGCU5176748 | H32: 500000 | I32: 0482592 | J32: 13/10/2025 | Q32: =S32/1.08 -> 1430000 | R32: =S32-Q32 -> 114400 | S32: 1544400 | T32: 141484 | U32: 45941 | V32: CÔNG TYCỔ PHẦN CẢNG CONTAINER QUỐC TẾ HATECO HẢI PHÒNG | AC32: =H32+M32+S32+Y32 -> 2044400 | AF32: Lấy TP - TS EX - Hạ Lạch Huyện | AH32: HATECO | AL32: =VLOOKUP(D32,'web CSHT'!$J$4:$Q$18000,8,0) -> #N/A
A33: =ROW()-21 -> 12 | B33: =VLOOKUP(G33,[3]T10!$Q$6:$S$1576,3,0) -> 45943 | C33: HL-78191313 | D33: 307848713560 | E33: 40HC | F33: VB-25/52490 | G33: HLBU1687684 | H33: 500000 | I33: 0482597 | J33: 13/10/2025 | Q33: =S33/1.08 -> 1430000 | R33: =S33-Q33 -> 114400 | S33: 1544400 | T33: 141743 | U33: 45943 | V33: CÔNG TYCỔ PHẦN CẢNG CONTAINER QUỐC TẾ HATECO HẢI PHÒNG | AC33: =H33+M33+S33+Y33 -> 2044400 | AF33: Lấy TP - TS EX - Hạ Lạch Huyện | AH33: HATECO | AL33: =VLOOKUP(D33,'web CSHT'!$J$4:$Q$18000,8,0) -> #N/A
A34: =ROW()-21 -> 13 | B34: =VLOOKUP(G34,[3]T10!$Q$6:$S$1576,3,0) -> 45942 | C34: HL-78191313 | D34: 307848857060 | E34: 40HC | F34: VB-25/52491 | G34: HLBU2060359 | H34: 500000 | I34: 0482581 | J34: 13/10/2025 | Q34: =S34/1.08 -> 1430000 | R34: =S34-Q34 -> 114400 | S34: 1544400 | T34: 141705 | U34: 45942 | V34: CÔNG TYCỔ PHẦN CẢNG CONTAINER QUỐC TẾ HATECO HẢI PHÒNG | AC34: =H34+M34+S34+Y34 -> 2044400 | AF34: Lấy TP - TS EX - Hạ Lạch Huyện Connect | AH34: HATECO | AL34: =VLOOKUP(D34,'web CSHT'!$J$4:$Q$18000,8,0) -> #N/A
A35: =ROW()-21 -> 14 | B35: =VLOOKUP(G35,'[3]T9.25 SW '!$Q$432:$S$1581,3,0) -> 45929 | C35: 257432252 | D35: 307805510520 | E35: 40 khô | F35: VB-25/52385 | G35: MRKU2826870 | H35: 250000 | I35: 0470822 | J35: 45932 | AC35: =H35+M35+S35+Y35 -> 250000 | AL35: =VLOOKUP(D35,'web CSHT'!$J$4:$Q$18000,8,0) -> #N/A
A36: =ROW()-21 -> 15 | B36: =VLOOKUP(G36,'[3]T9.25 SW '!$Q$432:$S$1581,3,0) -> 45927 | C36: 259591289 | D36: 307805567440 | E36: 40 khô | F36: VB-25/52386 | G36: HASU5183873 | H36: 500000 | I36: 0466533 | J36: 30/09/2025 | AC36: =H36+M36+S36+Y36 -> 500000 | AF36: Truck : ICD Tri Phương - Hateco | AL36: =VLOOKUP(D36,'web CSHT'!$J$4:$Q$18000,8,0) -> #N/A
A37: =ROW()-21 -> 16 | B37: =VLOOKUP(G37,'[3]T9.25 SW '!$Q$432:$S$1581,3,0) -> 45929 | C37: 258283048 | D37: 307810452260 | E37: 40 khô | F37: VB-25/52394 | G37: MRSU3992204 | H37: 500000 | I37: 0473183 | J37: 45934 | AC37: =H37+M37+S37+Y37 -> 500000 | AF37: Truck : ICD Tri Phương - Hateco | AL37: =VLOOKUP(D37,'web CSHT'!$J$4:$Q$18000,8,0) -> #N/A
A38: =ROW()-21 -> 17 | B38: =VLOOKUP(G38,'[3]T9.25 SW '!$Q$432:$S$1581,3,0) -> 45930 | C38: 257432252 | D38: 307810507820 | E38: 40 khô | F38: VB-25/52389 | G38: MRKU2940712 | H38: 500000 | I38: 0470846 | J38: 45932 | AC38: =H38+M38+S38+Y38 -> 500000 | AF38: Truck : ICD Tri Phương - Hateco | AL38: =VLOOKUP(D38,'web CSHT'!$J$4:$Q$18000,8,0) -> #N/A
A39: =ROW()-21 -> 18 | B39: =VLOOKUP(G39,'[3]T9.25 SW '!$Q$432:$S$1581,3,0) -> 45930 | C39: 257432252 | D39: 307810697300 307810668010 | E39: 40 khô | F39: VB-25/52396 VS-25/51489 | G39: MRKU4491143 | H39: 500000 | I39: 0468519 | J39: 45931 | AC39: =H39+M39+S39+Y39 -> 500000 | AF39: Truck : ICD Tri Phương - Hateco | AL39: =VLOOKUP(D39,'web CSHT'!$J$4:$Q$18000,8,0) -> #N/A
A40: =ROW()-21 -> 19 | B40: =VLOOKUP(G40,'[3]T9.25 SW '!$Q$432:$S$1581,3,0) -> 45930 | C40: 258096267 | D40: 307810951400 | E40: 40 khô | F40: VB-25/52390 | G40: MRSU4078831 | H40: 500000 | I40: 0470847 | J40: 45932 | AC40: =H40+M40+S40+Y40 -> 500000 | AF40: Truck : ICD Tri Phương - Hateco | AL40: =VLOOKUP(D40,'web CSHT'!$J$4:$Q$18000,8,0) -> #N/A
A41: =ROW()-21 -> 20 | B41: =VLOOKUP(G41,'[3]T9.25 SW '!$Q$432:$S$1581,3,0) -> 45930 | C41: 258283048 | D41: 307815448640 | E41: 40 khô | F41: VB-25/52401 | G41: MRSU3141713 | H41: 500000 | I41: 0473200 | J41: 45934 | AC41: =H41+M41+S41+Y41 -> 500000 | AF41: Truck : ICD Tri Phương - Hateco | AL41: =VLOOKUP(D41,'web CSHT'!$J$4:$Q$18000,8,0) -> #N/A
A42: =ROW()-21 -> 21 | B42: 45943 | C42: 259099228 | D42: =VLOOKUP(G42,[4]Sheet1!$I$188:$Q$205000,9,0) -> 307853072720 | E42: 40 khô | F42: VB-25/52493 | G42: HASU4911995 | H42: 250000 | I42: 0486998 | J42: 16/10/2025 | AC42: =H42+M42+S42+Y42 -> 250000 | AL42: =VLOOKUP(D42,'web CSHT'!$J$4:$Q$18000,8,0) -> #N/A
A43: =ROW()-21 -> 22 | B43: 45943 | C43: 259099228 | D43: =VLOOKUP(G43,[4]Sheet1!$I$188:$Q$205000,9,0) -> 307853097550 | E43: 40 khô | F43: VB-25/52486 | G43: MRKU5214740 | H43: 250000 | I43: 0487012 | J43: 16/10/2025 | AC43: =H43+M43+S43+Y43 -> 250000 | AL43: =VLOOKUP(D43,'web CSHT'!$J$4:$Q$18000,8,0) -> #N/A
A44: =ROW()-21 -> 23 | B44: 45944 | C44: 259098334 | D44: =VLOOKUP(G44,[4]Sheet1!$I$188:$Q$205000,9,0) -> 307853158010 | E44: 40 khô | F44: VB-25/52497 | G44: MRKU3521541 | H44: 250000 | I44: 0488243 | J44: 45947 | AC44: =H44+M44+S44+Y44 -> 250000 | AL44: =VLOOKUP(D44,'web CSHT'!$J$4:$Q$18000,8,0) -> #N/A
...

Sheet web CSHT
F4: STT | G4: Xem BL | H4: BL chuyển đổi | I4: Tải về | J4: Số tờ khai | K4: Ngày tờ khai | L4: Loại hình | M4: Mẫu/ Ký hiệu | N4: Số biên lai | O4: Ngày biên lai | P4: Trạng thái | Q4: Tổng tiền(vnđ) | R4: Mã tra cứu
F5: 1 | G5: Xem | H5: Xem | I5: Tải về | J5: 107973124450 | K5: 46062 | L5: E11 TF003 | M5: 01BLP0-001/ VC-24E | N5: 1083328 | O5: 46063 | P5: Biên lai gốc | Q5: 500 | R5: L2RHXYCU5P
F6: 2 | G6: Xem | H6: Xem | I6: Tải về | J6: 308233036000 | K6: 46059 | L6: E42 TF003 | M6: 01BLP0-001/ VT-24E | N6: 650607 | O6: 46063 | P6: Biên lai gốc | Q6: 250 | R6: CYI4CP1U5V
