Workbook

Sheet XUẤT-HPH
A1: CỘNG HÒA XÃ HỘI CHỦ NGHĨA VIỆT NAM
A2: Độc lập - Tự do - Hạnh Phúc
A4: STATEMENT ACCOUNT FOR EXPORT CUSTOM CLEARANCE AND TRANSPORTATION FEE
A6: Căn cứ vào tình hình thực tế thực hiện,
A7: Chúng tôi gồm:
A8: BÊN MUA: CÔNG TY TNHH CANON VIỆT NAM - CHI NHÁNH TIÊN SƠN
A9: Địa chỉ: Số 12, đường TS10, Khu công nghiệp Tiên Sơn, Xã Đại Đồng, Tỉnh Bắc Ninh, Việt Nam
A10: MST: 0101125340002
A11: Đại diện: | D11: Chức vụ:
A13: BÊN BÁN: CÔNG TY CỔ PHẦN MBF
A14: Địa chỉ: Số 58 Xóm Giếng, Thôn Cổ Điển A, Xã Thanh Trì, Thành phố Hà Nội, Việt Nam
A15: MST: 0105040296
A16: Đại diện: | D16: Chức vụ:
A17: Cùng đối chiếu như sau:
N18: Debit No.: | O18: ='COVER DN XUẤT'!D18 -> #REF!
N19: Date | O19: ='COVER DN XUẤT'!D19 -> #REF!
A21: STT | B21: Tuyến vận chuyển | C21: Ngày vận chuyển | D21: BL/ BKG | E21: Tờ khai | F21: Loại Conts | G21: CVN Invoice no | H21: Số Conts | I21: Biển kiểm soát/ Số hiệu sà lan | J21: Cước vận chuyển (chưa VAT) | K21: Lưu ca | L21: Tờ khai không phơi | M21: Phí tái sử dụng container rỗng | N21: Phí thanh lý tờ khai | O21: Tổng tiền | P21: Ghi chú
A22: =ROW()-21 -> 1 | B22: =VLOOKUP(P22,'chuyển 26.12'!$O$5:$P$6000,2,0) -> #N/A | C22: 46038 | D22: 237500707611 | E22: =VLOOKUP(H22,[1]Sheet1!$I$1:$Q$180000,9,0) -> 308158278210 | F22: 40HC | G22: VS-26/50066 | H22: EMCU8313605 | I22: 29H-81871 | J22: 3588286 | N22: 100000 | O22: =SUM(J22:N22) -> 3688286 | P22: Lấy HPH - TS EX - Hạ HPH Disconnect
A23: =ROW()-21 -> 2 | B23: =VLOOKUP(P23,'chuyển 26.12'!$O$5:$P$6000,2,0) -> #N/A | C23: 46038 | D23: HPH26A00675 | E23: =VLOOKUP(H23,[1]Sheet1!$I$1:$Q$180000,9,0) -> 308158323820 | F23: 40HC | G23: VF-26/50009 | H23: NSSU7171637 | I23: 29E-38441 | J23: 3888286 | N23: 100000 | O23: =SUM(J23:N23) -> 3988286 | P23: Lấy HPH - TS EX - Hạ HPH Connect
A24: =ROW()-21 -> 3 | B24: =VLOOKUP(P24,'chuyển 26.12'!$O$5:$P$6000,2,0) -> #N/A | C24: 46038 | D24: 237500707611 | E24: =VLOOKUP(H24,[1]Sheet1!$I$1:$Q$180000,9,0) -> 308158430550 | F24: 40HC | G24: VS-26/50065 | H24: BMOU6012145 | I24: 29H-81743 | J24: 3588286 | N24: 100000 | O24: =SUM(J24:N24) -> 3688286 | P24: Lấy HPH - TS EX - Hạ HPH Disconnect
A25: =ROW()-21 -> 4 | B25: =VLOOKUP(P25,'chuyển 26.12'!$O$5:$P$6000,2,0) -> #N/A | C25: 46038 | D25: 237500707611 | E25: =VLOOKUP(H25,[1]Sheet1!$I$1:$Q$180000,9,0) -> 308158509650 | F25: 40HC | G25: VS-26/50067 | H25: EGSU9553960 | I25: 29E-28914 | J25: 3888286 | N25: 100000 | O25: =SUM(J25:N25) -> 3988286 | P25: Lấy HPH - TS EX - Hạ HPH Connect
A26: =ROW()-21 -> 5 | B26: =VLOOKUP(P26,'chuyển 26.12'!$O$5:$P$6000,2,0) -> #N/A | C26: 46038 | D26: SGN2987352 | E26: =VLOOKUP(H26,[1]Sheet1!$I$1:$Q$180000,9,0) -> 308158360000 | F26: 40HC | G26: VH-26/50087 | H26: TRHU5424799 | I26: 15H-05911 | J26: 2985312 | N26: 100000 | O26: =SUM(J26:N26) -> 3085312 | P26: Lấy Hưng Yên - RU TS EX - Hạ HPH
A27: =ROW()-21 -> 6 | B27: =VLOOKUP(P27,'chuyển 26.12'!$O$5:$P$6000,2,0) -> #N/A | C27: 46038 | D27: SGN2991014 | E27: =VLOOKUP(H27,[1]Sheet1!$I$1:$Q$180000,9,0) -> 308158391130 | F27: 40HC | G27: VH-26/50089 | H27: TCNU7535165 | I27: 15H-18666 | J27: 2985312 | N27: 100000 | O27: =SUM(J27:N27) -> 3085312 | P27: Lấy Hưng Yên - RU TS EX - Hạ HPH
A28: =ROW()-21 -> 7 | B28: =VLOOKUP(P28,'chuyển 26.12'!$O$5:$P$6000,2,0) -> #N/A | C28: 46041 | D28: BHAIC26000188 | E28: =VLOOKUP(H28,[1]Sheet1!$I$1:$Q$180000,9,0) -> 308163768160 | F28: 40HC | G28: VS-26/50079 | H28: REGU5201120 | I28: 29E-28922 | J28: 3888286 | N28: 100000 | O28: =SUM(J28:N28) -> 3988286 | P28: Lấy HPH - TS EX - Hạ HPH Connect
A29: =ROW()-21 -> 8 | B29: =VLOOKUP(P29,'chuyển 26.12'!$O$5:$P$6000,2,0) -> #N/A | C29: 46041 | D29: 6438798511 | E29: =VLOOKUP(H29,[1]Sheet1!$I$1:$Q$180000,9,0) -> 308163870250 | F29: 40HC | G29: VS-26/50074 | H29: TIIU5347234 | I29: 29H-81846 | J29: 2697592 | N29: 100000 | O29: =SUM(J29:N29) -> 2797592 | P29: Lấy HPH - TS IM - RU TS EX - Hạ HPH
A30: =ROW()-21 -> 9 | B30: =VLOOKUP(P30,'chuyển 26.12'!$O$5:$P$6000,2,0) -> #N/A | C30: 46042 | D30: 6438798511 | E30: =VLOOKUP(H30,[1]Sheet1!$I$1:$Q$180000,9,0) -> 308169652730 | F30: 40HC | G30: VS-26/50089 | H30: CSNU8639981 | I30: 15C-02338 | J30: 2985312 | N30: 100000 | O30: =SUM(J30:N30) -> 3085312 | P30: Lấy Hưng Yên - RU TS EX - Hạ HPH
A31: =ROW()-21 -> 10 | B31: =VLOOKUP(P31,'chuyển 26.12'!$O$5:$P$6000,2,0) -> #N/A | C31: 46043 | D31: 237600063367 | E31: 308173905600 | F31: 20DC | G31: VH-26/50108 | H31: EITU3162502 | I31: 29E-38441 | J31: 3588286 | N31: 100000 | O31: =SUM(J31:N31) -> 3688286 | P31: Lấy HPH - TS EX - Hạ HPH Disconnect
A32: =ROW()-21 -> 11 | B32: =VLOOKUP(P32,'chuyển 26.12'!$O$5:$P$6000,2,0) -> #N/A | C32: 46045 | D32: 237500733123 | E32: =VLOOKUP(H32,[1]Sheet1!$I$1:$Q$180000,9,0) -> 308182232540 | F32: 40HC | G32: VH-26/50120 | H32: EGSU6484249 | I32: 29E-38562 | J32: 3588286 | N32: 100000 | O32: =SUM(J32:N32) -> 3688286 | P32: Lấy HPH - TS EX - Hạ HPH Disconnect
A33: =ROW()-21 -> 12 | B33: =VLOOKUP(P33,'chuyển 26.12'!$O$5:$P$6000,2,0) -> #N/A | C33: 46045 | D33: 237500736122 | E33: =VLOOKUP(H33,[1]Sheet1!$I$1:$Q$180000,9,0) -> 308181125140 | F33: 40HC | G33: VS-26/50113 | H33: TGBU6583045 | I33: 29H-81743 | J33: 3888286 | N33: 100000 | O33: =SUM(J33:N33) -> 3988286 | P33: Lấy HPH - TS EX - Hạ HPH Connect
A34: =ROW()-21 -> 13 | B34: =VLOOKUP(P34,'chuyển 26.12'!$O$5:$P$6000,2,0) -> #N/A | C34: 46045 | D34: 237500737447 | E34: =VLOOKUP(H34,[1]Sheet1!$I$1:$Q$180000,9,0) -> 308182479050 | F34: 40HC | G34: VS-26/50107 | H34: EGHU9330270 | I34: 29E-38441 | J34: 3588286 | N34: 100000 | O34: =SUM(J34:N34) -> 3688286 | P34: Lấy HPH - TS EX - Hạ HPH Disconnect
A35: =ROW()-21 -> 14 | B35: =VLOOKUP(P35,'chuyển 26.12'!$O$5:$P$6000,2,0) -> #N/A | C35: 46046 | D35: 237500737447 | E35: =VLOOKUP(H35,[1]Sheet1!$I$1:$Q$180000,9,0) -> 308184601230 | F35: 40HC | G35: VS-26/50115 | H35: TIIU5457859 | I35: 29E-28922 | J35: 3588286 | N35: 100000 | O35: =SUM(J35:N35) -> 3688286 | P35: Lấy HPH - TS EX - Hạ HPH Disconnect
A36: =ROW()-21 -> 15 | B36: =VLOOKUP(P36,'chuyển 26.12'!$O$5:$P$6000,2,0) -> #N/A | C36: 46046 | D36: 237500736122 | E36: =VLOOKUP(H36,[1]Sheet1!$I$1:$Q$180000,9,0) -> 308184642050 | F36: 40HC | G36: VS-26/50112 | H36: FFAU1594240 | I36: 29E-28914 | J36: 3588286 | N36: 100000 | O36: =SUM(J36:N36) -> 3688286 | P36: Lấy HPH - TS EX - Hạ HPH Disconnect
A37: =ROW()-21 -> 16 | B37: =VLOOKUP(P37,'chuyển 26.12'!$O$5:$P$6000,2,0) -> #N/A | C37: 46046 | D37: 237500733123 | E37: =VLOOKUP(H37,[1]Sheet1!$I$1:$Q$180000,9,0) -> 308184728520 | F37: 40HC | G37: VH-26/50128 | H37: EGSU6484172 | I37: 29H-81871 | J37: 3888286 | N37: 100000 | O37: =SUM(J37:N37) -> 3988286 | P37: Lấy HPH - TS EX - Hạ HPH Connect
A38: =ROW()-21 -> 17 | B38: =VLOOKUP(P38,'chuyển 26.12'!$O$5:$P$6000,2,0) -> #N/A | C38: 46046 | D38: 237500733123 | E38: =VLOOKUP(H38,[1]Sheet1!$I$1:$Q$180000,9,0) -> 308184527510 | F38: 40HC | G38: VH-26/50129 | H38: EGSU6489718 | I38: 29H-81921 | J38: 3888286 | N38: 100000 | O38: =SUM(J38:N38) -> 3988286 | P38: Lấy HPH - TS EX - Hạ HPH Connect
A39: =ROW()-21 -> 18 | B39: =VLOOKUP(P39,'chuyển 26.12'!$O$5:$P$6000,2,0) -> #N/A | C39: 46048 | D39: 237500736122 | E39: =VLOOKUP(H39,[1]Sheet1!$I$1:$Q$180000,9,0) -> 308188076360 | F39: 40HC | G39: VH-26/50138 | H39: EGHU9777247 | I39: 29H-88946 | J39: 3588286 | N39: 100000 | O39: =SUM(J39:N39) -> 3688286 | P39: Lấy HPH - TS EX - Hạ HPH Disconnect
A40: =ROW()-21 -> 19 | B40: =VLOOKUP(P40,'chuyển 26.12'!$O$5:$P$6000,2,0) -> #N/A | C40: 46048 | D40: HANA57597700 | E40: =VLOOKUP(H40,[1]Sheet1!$I$1:$Q$180000,9,0) -> 308188091320 | F40: 40HC | G40: VS-26/50105 | H40: HMMU7026820 | I40: 29H-81607 | J40: 3588286 | N40: 100000 | O40: =SUM(J40:N40) -> 3688286 | P40: Lấy HPH - TS EX - Hạ HPH Disconnect
A41: =ROW()-21 -> 20 | B41: =VLOOKUP(P41,'chuyển 26.12'!$O$5:$P$6000,2,0) -> #N/A | C41: 46049 | D41: 237500733123 | E41: =VLOOKUP(H41,[1]Sheet1!$I$1:$Q$180000,9,0) -> 308193111610 | F41: 40HC | G41: VH-26/50144 | H41: GCXU6443400 | I41: 29E-28922 | J41: 3588286 | N41: 100000 | O41: =SUM(J41:N41) -> 3688286 | P41: Lấy HPH - TS EX - Hạ HPH Disconnect
A42: =ROW()-21 -> 21 | B42: =VLOOKUP(P42,'chuyển 26.12'!$O$5:$P$6000,2,0) -> #N/A | C42: 46051 | D42: 237600097369 | E42: =VLOOKUP(H42,[1]Sheet1!$I$1:$Q$180000,9,0) -> 308202099500 | F42: 40HC | G42: VH-26/50156 | H42: EGSU1600794 | I42: 29H-81921 | J42: 3888286 | N42: 100000 | O42: =SUM(J42:N42) -> 3988286 | P42: Lấy HPH - TS EX - Hạ HPH Connect
A43: =ROW()-21 -> 22 | B43: =VLOOKUP(P43,'chuyển 26.12'!$O$5:$P$6000,2,0) -> #N/A | C43: 46051 | D43: 237600056956 | E43: =VLOOKUP(H43,[1]Sheet1!$I$1:$Q$180000,9,0) -> 308202123520 | F43: 40HC | G43: VS-26/50138 | H43: TLLU7977255 | I43: 29H-81846 | J43: 3888286 | N43: 100000 | O43: =SUM(J43:N43) -> 3988286 | P43: Lấy HPH - TS EX - Hạ HPH Connect
A44: =ROW()-21 -> 23 | B44: =VLOOKUP(P44,'chuyển 26.12'!$O$5:$P$6000,2,0) -> #N/A | C44: 46051 | D44: SGN3036238 | E44: 308202052820 | F44: 40HC | G44: VH-26/50157 | H44: CMAU7489161 | I44: 15C-16755 | J44: 2985312 | N44: 100000 | O44: =SUM(J44:N44) -> 3085312 | P44: Lấy Hưng Yên - RU TS EX - Hạ HPH
...
